Workbook

Sheet Instructions & overview
C5: Bank Diagnostic
C6: INVEST: The Process & Toolkit for Unleashing SME Banking
C10: Last modified: Septmber 23rd, 2025 | E10: Contact details for further inquiries:
E11: karen.rodriguez@dalberg.com
E12: kusi.hornberger@dalberg.com
C14: OVERVIEW
C16: The Bank Diagnostic is an Excel-based template to help funders and banks identify capability gaps to be filled to effectively deliver SME banking. It offers a menu of options to inform technical assistance efforts or internal initiatives aimed at strengthening a bank’s SME banking capabilities.
C18: Focus audience:
C19: USE CASE
C21: The tool allows banks to self-assess and allows TA funders to identify their partner bank's existing capabilities and gaps in terms of SME banking across six assessment areas: 1) strategy, 2) talent and organizational structure, 3) competitive positioning, 4) operational processes, 5) products and value proposition, and 6) digital readiness. It helps inform strategic pathways and prioritize relevant TA opportunities to strengthen SME finance delivery. The Bank Diagnostic serves as a practical starting point for banks to understand their current capabilities relative to the best-in-class models for SME banking in order to enter the market or scale their existing business.
C23: OBJECTIVES
C25: 1. Assess banks'city and internal readiness to deliver SME banking using 30+ indicators focused on core institutional capabilities, including digital readiness. 2. Identify capacity-building opportunities to strengthen SME finance and accelerate digital transformation.
C27: GUIDANCE
C29: This file consists of seven tabs, including this one. Below is a high-level description of each tab, along with specific instructions on how users can interact with them to complete the bank diagnostic successfully.
C31: Tab Name | D31: Description | E31: Instructions
C33: Financial performance | D33: This tab presents a dashboard of key financial performance indicators that can be filled out for banks with an existing SME banking business. It offers a visual overview of performance in the SME segment. Filling out this tab is optional, as it depends on the availability of information. | E33: Complete the financial performance dashboard by collecting or requesting the necessary data to populate each indicator, including metrics related to portfolio size and growth, portfolio health, customer loyalty, SME revenue contribution, profitability, and productivity. The dashboard is designed to be flexible; users are encouraged to edit or add indicators as needed to suit the specific context or analytical goals. Please note that this dashboard should be adjusted to reflect relevant indicators based on banks availability of data and / or priorities of user
C34: Bank diagnostic | D34: This tab presents the Bank Diagnostic Framework, outlining key assessment areas and indicators, along with space for stakeholders to assign scores and provide rationale for each. It also includes guidance on how to automate and customize the tool to reflect users' varying priorities (e.g., by adding or removing indicators). Specific questions on digital readiness are included in a distinct format. | E34: Edit the following two cells across assessment areas and indicators: '1. Score: To input scores per category on a High/Medium/Low or Yes/No scale 2. Rationale: To provide a justification or explanation for the selected score
C35: Examples | D35: These tabs include examples of how to score banks across assessment areas and indicators. They provide illustrative scores and rationales based solely on secondary data. As such, the examples are for demonstration purposes only and are intended to support stakeholders in conducting their own bank diagnostics. The information presented is not fully accurate and should not be used as a definitive reference. | E35: Use these examples as guidance for scoring and what type of rationale to include across assessment areas.
C36: Methodology | D36: This tab provides an overview of the methodology used to obtain the bank diagnostic results, including the scoring logic and the roadmaps for mitigating the identified gaps. | E36: Review the scoring guidance and focus area considerations. Add or remove categories as needed to align with your organization’s priorities.
C37: Results | D37: This tab provides an overview of the bank diagnostic results, highlighting the maturity level of each assessment area, including digital readiness. It also outlines suggested pathways to address the identified gaps. | E37: Consider the most pressing gaps and review the suggested strategies for strengthening SME banking. Engage relevant decision-making teams to help guide future analysis and interventions.
C39: USING THIS TOOL EFFECTIVELY
C41: SMEs are defined here as firms with 10–250 employees and revenues of USD 100K–15M. While definitions vary by market, this standard is used for consistency, while most tools also apply to informal or smaller enterprises.
C43: This tool is designed to be geography-agnostic and applicable across all banks and TA funders. It is intended as a flexible resource that can be adapted and customized to fit each organization's specific needs, goals, and contextual realities. The tool serves as a starting point that can be built upon and tailored as needed. Users are encouraged to treat this as a living tool, one that can be updated over time to reflect emerging learnings and strategic shifts. For more information, reference the tool's user guide.
C45: The Bank Diagnostic is a core component of INVEST: The Process & Toolkit for Unleashing SME Banking, a public resource that helps banks and TA funders strengthen SME banking operations. It was developed through a highly consultative process and draws on learnings from experienced ecosystem experts. The Bank Diagnostic is closely linked to other tools from the toolkit, especially in terms of strategic and TA recommendations across focus areas to address identified capability gaps.
D46: Move to the next sheet to begin assessing the SME readiness of your organization or partner bank!

Sheet Financial performance
D3: Bank's Overall SME Financial Performance
D4: •Before initiating the bank diagnostic, please gather or request the necessary data to populate the following key indicators. These will provide a comprehensive overview of the bank’s financial performance. If this information is not available, leave the tab empty. •In addition to the metrics listed, please include any other relevant indicators that may enhance the analysis, such as operational efficiency, net interest margins, profit per SME officer, or others that reflect segment-level financial performance.
C18: Year | D18: SME portfolio size (USD million) | E18: SME share | J18: Year | K18: SME revenue (USD million) | L18: Overall revenue (USD million) | Q18: Year | R18: SME CIR | S18: Overall CIR
C19: 2020 | D19: 5 | E19: 0.05 | J19: 2020 | K19: 130 | L19: 720 | Q19: 2020 | R19: 0.68 | S19: 0.54
C20: 2021 | D20: 5.5 | E20: 0.07 | J20: 2021 | K20: 145 | L20: 760 | Q20: 2021 | R20: 0.65 | S20: 0.54
C21: 2022 | D21: 5.7 | E21: 0.07 | J21: 2022 | K21: 160 | L21: 820 | Q21: 2022 | R21: 0.65 | S21: 0.53
C22: 2023 | D22: 7 | E22: 0.1 | J22: 2023 | K22: 170 | L22: 850 | Q22: 2023 | R22: 0.62 | S22: 0.54
C23: 2024 | D23: 7.5 | E23: 0.12 | J23: 2024 | K23: 210 | L23: 980 | Q23: 2024 | R23: 0.59 | S23: 0.48
J24: Average | K24: =AVERAGE(K19:K23) -> 163 | L24: =AVERAGE(L19:L23) -> 826
C47: Year | D47: SME NPS | E47: Overall NPS | J47: Year | K47: SMEs NPL | L47: Overall NPL | Q47: Year | R47: Loans per officer SME segment | S47: Overall loans per officer
C48: 2020 | D48: 3 | E48: 45 | J48: 2020 | K48: 0.08 | L48: 0.03 | Q48: 2020 | R48: 90 | S48: 150
C49: 2021 | D49: 5 | E49: 45 | J49: 2021 | K49: 0.06 | L49: 0.03 | Q49: 2021 | R49: 90 | S49: 150
C50: 2022 | D50: 15 | E50: 46 | J50: 2022 | K50: 0.04 | L50: 0.025 | Q50: 2022 | R50: 95 | S50: 150
C51: 2023 | D51: 35 | E51: 48 | J51: 2023 | K51: 0.04 | L51: 0.025 | Q51: 2023 | R51: 102 | S51: 150
C52: 2024 | D52: 30 | E52: 50 | J52: 2024 | K52: 0.025 | L52: 0.02 | Q52: 2024 | R52: 115 | S52: 150

Sheet Bank diagnostic
A1: Let
D4: Bank diagnostic
D5: • In this tab, you can complete the Bank diagnostic for your bank or a partner bank. • Start by entering information about the specific bank you are assessing, including its name, country of operation, and type. For "Bank type," tiers are typically defined by the size of the bank’s assets: Tier 1 banks usually hold assets of around $100 billion or more, Tier 2 banks hold between $1 billion and $100 billion, and Tier 3 banks have assets of $1 billion or less. These ranges may vary by country and should be adjusted to local market conditions where appropriate. • Please enter scores for each of the five assessment areas in column E, and provide a brief justification for each score in column F. • The questions specifically focused on digital capabilities can be found within the different assessment areas with the following format: • Completing the assessment effectively requires access to primary information. To this end, it is recommended to conduct interviews with multiple bank staff, as indicated in column I. Suggested interview questions are listed in column D to support this process and are also compiled in a standalone Interview Guide that accompanies this tool. • Automation and customization guidelines can be found in columns K and L.
D9: Bank profile | H9: Overall standing
D10: Name: | F10: Bank X | H10: {=_xlfn.IFS(H11<Methodology!G30,"Low maturity",H11<Methodology!G29,"Mid maturity",H11>=Methodology!G29,"High maturity")} -> #VALUE!
D11: Country of operation: | H11: {=_xlfn.LET(_xlpm.scores, _xlfn._xlws.FILTER(F19:F105, F19:F105<>""),SUMPRODUCT((_xlpm.scores="High")*Methodology!F15+(_xlpm.scores="Medium")*Methodology!F16+((_xlpm.scores="Low") + (_xlpm.scores="No data"))*Methodology!F17+(_xlpm.scores="Yes")*Methodology!I15+(_xlpm.scores="No")*Methodology!I16))} -> 128
D12: Bank type:
D16: Criteria | E16: Interview questions and guide | F16: Score | G16: Rationale | H16: Scoring guidance | I16: Direction | J16: Assessment tips | K16: Type of source | L16: Notes on customization | M16: Automation guidelines
D17: 1. Strategy
C18: # | D18: Overall strategy
C19: 1.1 | D19: 1.1 SME banking is a top priority for the bank | E19: Is SME banking among the bank's top strategic priorities for the next 2–3 years? How would it rank compared to other key priorities? | F19: Medium | H19: High: SME banking is explicitly named as one of the bank’s top 3 short-term strategic priorities Medium: SME banking is listed among the top 4–10 strategic priorities Low: SME banking is not clearly reflected among the bank's top strategic priorities or is absent from current strategy documentation | I19: Positive, given banks that consider SME programs a high priority are likely committed to their execution | J19: Interview at least two bank staff, including a senior leader (e.g., COO, CEO, or CSO), to ensure a well-rounded perspective | K19: Primary | M19: If recording is allowed, use ChatGPT or a similar AI tool to analyze the transcripts of interviews and identify key takeaways related to the bank's SME strategy. Prompt example: “Analyze these transcripts to extract insights to answer the following questions related to the bank’s SME strategy. If information is missing or unclear in the transcripts, search external public sources (e.g., annual reports, investor presentations, strategy briefs) to complement your responses. For each question: i) Summarize the relevant insight based on the transcript, ii) Complement information from public documents if helpful, iii) Include one short quote (from either the transcript or a public source) as supporting evidence Questions to answer: 1.1 Is SME banking a top strategic priority for the bank? 1.2 Does the SME portfolio represent a significant share of the bank’s overall business? 1.3 Are SME goals clearly defined, time-bound, and reflected across departments? 1.4 Are SME strategies and outcomes reviewed regularly by senior leadership? 1.5 Are SME strategies supported by structured, multi-year investment plans? 1.6 Is the SME strategy embedded across departments and delivery channels (e.g., credit, ops, digital)? 1.7 Are SME impact goals (e.g., inclusion, gender, climate) defined, tracked, and reviewed? 1.8 Has the bank successfully delivered SME-related change initiatives in the past 3–5 years (e.g., product rollout, migration, segment launches)?" Note: Any AI-generated findings should be reviewed and validated by the user to ensure accuracy and contextual relevance.
C20: 1.2 | D20: 1.2 The targeted or current SME portfolio represents a significant share of the bank’s overall business | E20: What is the current share of SME lending in the bank's total business? What share is the bank targeting over the next few years? | F20: High | H20: High: SMEs make up ≥20% of the bank’s current or targeted lending Medium: SMEs represent 10–19% of the bank’s lending Low: SMEs represent less than 10% of the bank’s lending | I20: Positive, as a high SME share of the loan book signals that SMEs are a core commercial focus, likely supported by resource allocation | J20: Interview at least two bank staff, including a senior leader (e.g., COO, CEO, or CSO), to ensure a well-rounded perspective | K20: Primary
C21: 1.3 | D21: SME strategy
C22: 1.3 | D22: 1.3 SME goals are clearly defined and time-bound | E22: Has the bank defined an SME segment with specific goals? If so, what are their time horizons, and how frequently are they tracked? | F22: High | H22: High: The bank has defined SME as a distinct segment with specific and measurable goals with 3–5 year timelines, tied to planning cycles Medium: SME goals exist but are not concrete, time-bound, or lack consistent tracking and updating Low: SME-related goals are vague or aspirational, with no actionable framework | I22: Positive, as clear, time-bound SME goals that are shared across teams suggest strategic cohesion and prioritization | J22: Interview the SME Business Lead (or related positions) or a senior leader (e.g., CSO) to validate Complement with secondary information, such as annual reports and investor relations presentations | K22: Both
C23: 1.4 | D23: 1.4 SME strategy and outcomes are periodically reviewed by senior leadership | E23: Do leadership members oversee SME banking operations? If so, who? How frequently does this person review progress on the SME strategy? | F23: Low | H23: High: SME operations and outcomes are closely monitored by at least one senior executive who is accountable for executing and reviewing the overall strategy on a quarterly basis Medium: SME operations are monitored but not reviewed as frequently by senior leadership (e.g., only annually) Low: No structured oversight or accountability is limited to middle management staff | I23: Positive, as periodic strategy reviews by senior leadership ensure accountability and course correction aligned with executive decision cycles | J23: Interview a senior leader (e.g., CSO or CEO) to validate | K23: Primary | L23: Adjust to reflect the organization’s governance structure and team composition, while ensuring appropriate leadership oversight
C24: 1.5 | D24: 1.5 SME strategy is supported by structured, multi-year investment plans | E24: Does the bank have defined investment plans to deliver on its SME strategy? If so, what are the execution timelines, and what resources have been allocated to support it? | F24: High | H24: High: The bank has defined both medium-term (1-3 year horizon) and long-term (4-6 year horizon) investment plans and allocated sufficient resources in alignment with SME goals Medium: There is an investment plan, but resource allocation or execution timelines are not as clearly defined (e.g., very long term) Low: There are no investment plans or if present these lack clear resource allocation and timelines for execution | I24: Positive, since the presence of both medium- and long-term investment plans reflects a credible roadmap and strong institutional commitment | J24: Interview a senior leader (e.g., CSO or CEO) and the SME Business Lead (or related positions) to validate Complement with internal budget documents or similar resources | K24: Primary | L24: It's common for small banks to receive a medium or low score, as they may not have the resources to develop multi-year investment plans
C25: 1.6 | D25: 1.6 SME strategy is embedded across departments and delivery channels | E25: Is the SME strategy reflected in the work of core teams (e.g., credit, risk, operations)? Are these teams held accountable for delivering on SME-related priorities? | F25: High | H25: High: The bank has a SME strategy that is known and reflected across core departments (e.g., credit, ops, risk, digital) and delivery teams (e.g., branches, agents, RMs). SME objectives and priorities are understood at the field level and included in branch plans Medium: SME priorities are partially reflected in support departments but weakly cascaded to delivery channels; some staff are aware, but ownership is uneven Low: There is not an SME strategy in place or there is little awareness or alignment on the SME strategy | I25: Positive, as a broad-based understanding of SME priorities across functions improves consistency in service delivery | J25: Interview the SME Business Lead (or related positions) to validate | K25: Primary | L25: Include specific core departments or teams
C26: 1.7 | D26: 1.7 SME impact goals have defined metrics and are consistently tracked | E26: Are there defined inclusion or impact goals for SME banking? If so, how frequently are these monitored? | F26: Low | H26: High: Inclusion KPIs (e.g., % loans to women-led or climate-aligned SMEs) are defined, tracked, and reviewed at least annually Medium: Inclusion KPIs are defined but not tracked periodically or at the SME level Low: Inclusion KPIs are not defined or tracked throughout the organization | I26: Positive, as the regular tracking of SME impact metrics demonstrates a commitment to measuring outcomes beyond disbursements and aligned with financial inclusion | J26: Interview the SME Business Lead (or related positions) to validate Complement with secondary information, such as annual reports and investor relations presentations | K26: Both | L26: Tailor to align with specific impact goals of interest (e.g., rural development, gender inclusion, job creation)
C27: 1.8 | D27: 1.8 Proven track record delivering strategic change initiatives (e.g., product rollout, digital migration, segment launch) | E27: Has the bank implemented any major strategic or operational initiatives in the past 3–5 years (e.g., new business segment, digital transformation, or product launch)? If so, what were the outcomes and how effectively were these initiatives delivered? | F27: High | H27: High: The bank has successfully implemented at least two strategic or operational initiatives in the past 3–5 years, with clear delivery outcomes and cross-functional coordination Medium: Some change initiatives were implemented but with delays, limited scale, or unclear outcomes Low: Limited or no record of executing structured change beyond business-as-usual operations | I27: Positive, since the successful delivery of change initiatives reflects strong execution, learning, and adaptation capacity, which can be leveraged to drive future SME initiatives | J27: Interview a senior leader (e.g., CSO, COO, or CEO) to validate | K27: Primary | L27: Include mainly if the bank has limited SME experience to validate its change management capacity
D28: 2. Talent and organizational structure
C29: 2.1 | D29: 2.1 Dedicated SME unit with defined roles and execution responsibility | E29: Does the bank have a dedicated SME unit with defined roles and responsibilities? If so, how many staff members are exclusively focused on SME-related activities? | F29: Low | H29: High: The bank has a full-time SME unit of at least 3–5 staff with defined roles and responsibilities across core departments (e.g., sales, credit, and product). The team has decision-making authority Medium: The bank has 1-2 designated staff members, but SME is one of many responsibilities or roles that they hold in the bank Low: No SME-specific staff or execution roles exist | I29: Positive, as the presence of a full-time, multi-functional SME team with clear responsibilities and decision-making authority indicates strong internal ownership and coordination capacity | J29: Interview a senior leader (e.g., CSO or CEO) or the SME Business Lead (or related positions) to validate Complement with secondary information, such as LinkedIn profiles and team composition on the bank's website | K29: Both | L29: Adjust the size of the SME team based on the overall staff capacity and scale of the organization | M29: If recording is allowed, use ChatGPT or a similar AI tool to analyze the transcripts of interviews and identify key takeaways related to the bank's SME talent and organizational structure. Prompt example: “Analyze these transcripts to extract insights to answer the following questions related to the bank’s SME team structure and collaboration. If information is missing or unclear in the transcripts, search external public sources (e.g., annual reports, org charts, bank websites) to complement your responses. For each question: i) Summarize the relevant insight based on the transcript; ii) Complement with public information if helpful, and iii) Include one short quote (from either the transcript or a public source) as supporting evidence. Questions to answer: 2.1 Does the bank have a dedicated SME unit with clear roles and execution responsibility? 2.2 Are SME performance targets and incentives defined across departments? 2.3 Are relevant trainings for SME banking provided to relevant staff?" Note: Any AI-generated findings should be reviewed and validated by the user to ensure accuracy and contextual relevance.
C30: 2.2 | D30: 2.2 SME staff have performance targets and incentives | E30: Do staff involved in SME banking have performance targets or incentives specifically tied to SME results? If so, which roles have KPIs? How are these encouraging performance? | F30: High | H30: High: SME KPIs (e.g., loan disbursement, NPLs, turnaround time, cross-sell) are embedded in the SME unit's performance evaluations, and incentives reward SME results Medium: SME KPIs exist but only for front-line or business development staff, or incentives are not sufficiently encouraging performance Low: There are no clearly defined SME KPIs or incentives | I30: Positive, as embedding SME performance metrics in team performance can reinforces strategic prioritization | J30: Interview the SME Business Lead (or related positions) to validate | K30: Primary
C31: 2.4 | D31: 2.3 Relevant trainings for SME banking are provided for relevant staff | E31: Does the bank offer SME-specific training for staff? If so, which staff members receive this training, and how frequently is it delivered? | F31: High | H31: High: Staff related to SME operations or strategy receive the pertinent training and have ongoing upskilling opportunities to properly execute their roles in the SME context Medium: SME specific training is not sufficiently provided, or is only provided to some staff Low: No SME-specific training or technical capacity-building is available | I31: Positive, since widespread SME-specific training ensures that staff are equipped with the knowledge and tools needed to serve the SME segment effectively | J31: Interview the SME Business Lead (or related positions) to validate | K31: Primary
D32: 3. Competitive positioning
C33: 3.1 | D33: 3.1 SME strategy is informed by market research and benchmarking | E33: Has the bank conducted any market research or competitive benchmarking focused on SME segments? If so, when was it done? How has it influenced SME strategy or product development? | F33: High | H33: High: The bank conducts market or client research (e.g., SME segmentation studies, behavioral data, competitor market share analysis) on at least a yearly basis, and findings have influenced strategy, product design, or delivery priorities Medium: Some SME-related research exists (e.g., old market studies or internal data analysis), but is not consistently updated or has limited influence on decision-making Low: No SME-specific research has been conducted, or insights are not used to shape strategy or service design | I33: Positive, as the use of structured SME research and competitor analysis ensures better-tailored products and services and overall positioning | J33: Interview the SME Business Lead (or related positions) to validate | K33: Primary | M33: If recording is allowed, use ChatGPT or a similar AI tool to analyze the transcripts of interviews and identify key takeaways related to the bank’s competitive SME positioning. Prompt example: “Analyze these transcripts to extract insights to answer the following questions related to SME market strategy and differentiation. If transcript information is missing or unclear, search public sources (e.g., bank websites, strategy decks, press releases) to strengthen responses. For each question: i) Summarize relevant insight from the transcript; ii) Complement with public material if available, and iii) Include a short quote from the transcript or source. Questions to answer: 3.1 Is SME strategy informed by market research and benchmarking? 3.2 Does the bank actively target SME segments with untapped market opportunity? 3.3 Is the SME value proposition well-recognized across the market? 3.4 Does the bank use data analytics to shape SME product delivery and innovation?" Note: Any AI-generated findings should be reviewed and validated by the user to ensure accuracy and contextual relevance.
C34: 3.2 | D34: 3.2 The bank actively identifies and targets SME segments with an uncaptured market potential | E34: Does the bank target specific SME segments? If so, how were these segments selected? Was the untapped market potential a factor in their selection? | F34: Low | H34: High: The bank deliberately targets SME segments that are underserved and show clear market potential, meaning limited competition from other banks and unmet demand Medium: The bank segments and targets SMEs, but selection is not clearly based on an untapped opportunity Low: The bank serves SMEs broadly without segment-specific targeting or consideration of competitive saturation | I34: Positive, because proactive targeting of high-potential SME segments improves the bank’s ability to differentiate in competitive markets | J34: Interview the SME Business Lead (or related positions) to validate | K34: Primary
C35: 3.3 | D35: 3.3 SME competitive positioning is well-recognized across the market | E35: Does the bank have a defined SME brand or value proposition? If so, how is it marketed and communicated to the public? | F35: High | H35: High: The bank has a distinct SME brand or value proposition that is consistently communicated across channels (e.g., website, marketing, physical branches) and recognized by clients or stakeholders Medium: The bank offers SME services and may reference SMEs in its materials, but lacks a clear value proposition or consistent branding that differentiates it from competitors Low: SME offerings are not visibly positioned or promoted. There is no SME-specific branding, value proposition, or messaging | I35: Positive, as a distinct and consistently communicated SME brand or value proposition enhances market visibility and reinforces the bank’s reputation as a serious SME player | J35: Interview a senior leader (e.g., CSO or CEO) or the SME Business Lead (or related positions) to validate Complement with secondary information, such as press coverage, award recognitions, and social media campaigns | K35: Secondary
C36: 3.4 | D36: 3.4 [Digital] The value proposition of SME banking is enhanced by data analytics and digital innovation | E36: Does the bank use market research or customer insights to guide SME banking priorities? How often is this done, and how consistently is it applied? | F36: Medium | H36: High: The SME value proposition is regularly enhanced through the use of data analytics or digital innovation (e.g., automated onboarding, digital credit scoring). These tools are actively used to shape SME product development or service delivery Medium: Some SME initiatives are informed by data or enhanced through digital strategies, but this is applied inconsistently or on a limited basis Low: SME offerings are rarely or never shaped by data analytics or digital tools | I36: Positive, as basing initiatives on market analyses ensures relevance, enhances SME uptake, and supports value-driven innovation | J36: Interview a senior leader (e.g., CIO or CTO) as well as key staff responsible for SME digital banking (e.g., Head of SME Banking or similar roles) | K36: Primary
D37: 4. Operational processes
C38: 4.1 | D38: 4.1 SME credit processes are flexible and adapted to typical access-to-finance constraints and priorities of SMEs | E38: Does the bank use credit processes specifically tailored to SME clients? If so, what are those processes? How institutionalized are these? | F38: Medium | H38: High: Credit assessment processes are meaningfully adapted to SME realities (e.g., cash-flow-based analysis, flexible collateral, data-driven models) and are consistently applied by staff handling SME lending Medium: Some SME-appropriate credit practices exist but are applied inconsistently or are not institutionalized Low: SME credit follows standard corporate models with no tailored features | I38: Positive, because when the bank’s credit processes are meaningfully tailored to SME realities, financial products can be offered more safely and inclusively to a broader SME customer base | J38: Interview the SME Business Lead (or related positions) or other internal experts (e.g., Head of Credit or Head of Risk) to validate | K38: Primary | M38: If recording is allowed, use ChatGPT or a similar AI tool to analyze the transcripts of interviews and identify key takeaways related to SME operational processes. Prompt example: “Analyze these transcripts to extract insights to answer the following questions about SME process design and execution. Where transcripts are incomplete, search public materials (e.g., product brochures, operations manuals, public client journeys) to fill gaps. For each question: i) Summarize the key insight from the transcript; ii) Complement with public information as needed, and iii) Include a short quote (from either source) to support your answer. Questions to answer: 4.1 Are SME credit processes flexible and adapted to client realities? 4.2 Does segmentation drive product and service tailoring for SMEs? 4.3 Do relationship managers deliver tailored engagement to SMEs? 4.4 Is broader client data analyzed to identify unserved SME clients and cross-sell opportunities and support credit assessments? 4.5 Is SME performance tracked through internal systems and routine reporting? 4.6 Are the key bank systems integrated and work smoothly to support SME operations? 4.7 Does the bank have a clear change management framework to ensure reliable SME operations? 4.8 How long does the bank usually take to launch a new SME digital feature? 4.9 Are SME digital services compliant with data privacy regulations?" Note: Any AI-generated findings should be reviewed and validated by the user to ensure accuracy and contextual relevance.
C39: 4.2 | D39: 4.2 Segmentation drives the design and tailoring of products and services | E39: Has the bank defined SME segments (e.g., by size, sector, lifecycle)? If so, how are those used to tailor products and services? | F39: High | H39: High: SME segments are well-defined (e.g., by size, lifecycle, sector) and actively shape product or service design (e.g., pricing, bundling, distribution). Segmentation is regularly reviewed and updated Medium: Key SME segments are identified but used only superficially in some aspects of product and service design Low: There is no clear SME segmentation, or segmentation exists but has no influence on product or service decisions | I39: Positive, as the use of clearly defined SME segments to shape product, pricing, and delivery strategies enables more relevant and effective offerings across client types | J39: Interview the SME Business Lead (or related positions) or other internal experts (e.g., Product Manager) to validate | K39: Primary
C40: 4.3 | D40: 4.3 Relationship managers deliver tailored engagement to SMEs | E40: Does the bank assign relationship managers or officers to SME clients? What does their engagement consist of? | F40: Medium | H40: High: Relationship managers or account officers are assigned to SME clients with defined portfolios and use structured engagement tools (e.g., CRM systems) Medium: There are SME focused staff who engage clients, but there are no consistent or standardized engagement practices Low: There is no relationship management model for SMEs, or interactions are reactive or handled by generalist staff | I40: Positive, since assigning relationship managers with dedicated SME portfolios ensures more consistent and targeted support that helps deepen long-term client relationships | J40: Interview the SME Business Lead (or related positions) or other internal experts (e.g., Lead Engagement Manager) to validate | K40: Primary
D41: 4.4 The bank analyzes broad client data to identify SME owners within other customer segments for cross-selling SME products and assessing creditworthiness | E41: Does the bank analyze broader customer data to identify existing clients from other segments (e.g., retail, corporate) who are SME owners or managers? If so, how is this data used to cross-sell SME banking products and assess creditworthiness? | F41: Medium | H41: High: The bank systematically analyzes broad client data (e.g., transaction history, product usage, private financial profiles) to proactively identify SME owners or managers among clients in other segments (e.g., retail, corporate) and consistently uses these insights to cross-sell SME banking products and support credit assessments Medium: The bank occasionally or partially uses broad client data to identify SME owners in other segments, but this is not systematic, and the insights not commonly used to support cross-selling or credit evaluation Low: The bank does not analyze or use client data to expand its SME portfolio | I41: Positive, since proactively analyzing broad client data enables banks to identify untapped SME opportunities within their existing customer base, improve cross-selling of SME products, and strengthen credit risk assessments | J41: Interview the SME Business Lead (or related positions) to validate
C42: 4.4 | D42: 4.5 SME banking is integrated into internal systems and performance tracked through routine reporting | E42: Is SME performance tracked in the bank's reporting systems? How frequently is it reviewed? | F42: High | H42: High: SME portfolio performance (e.g., loan volume, NPLs, product use, client growth, default risk, officer productivity) is integrated into the bank’s reporting systems and reviewed at least quarterly Medium: SME data is tracked in core reporting systems but not disaggregated, periodically updated, or reviewed Low: SME is not embedded into reporting systems, or there is no regular SME performance tracking | I42: Positive, because integrating SME performance metrics into core systems and reviewing them regularly enables continuous improvement and supports more responsive management of the segment | J42: Interview a senior leader (e.g., COO) or the SME Business Lead (or related positions) to validate | K42: Primary
C43: 4.5 | D43: 4.6 [Digital] Key data systems (CRM, loan origination system, API) are fully integrated to enable seamless information flow across departments and branches | E43: Are the bank’s key systems integrated and function smoothly to support SME digital operations? If so, are any manual steps or interventions still required? | F43: High | H43: High: All critical systems that support SME banking, like customer records, loan approvals, and payments, are fully integrated and work smoothly together across departments and branches Medium: Some systems are connected, but others (like credit or customer information) still require manual steps or data transfers Low: Most systems are separate, requiring staff to manually move information between them, which slows down processes and increases the risk of errors | I43: Positive, since integrated systems streamline workflows, reduce duplication, and improve the delivery of SME digital services. | J43: Interview a senior leader (e.g., CIO or CTO) as well as key staff responsible for SME digital banking (e.g., Head of SME Banking or similar roles) | K43: Primary
C44: 4.6 | D44: 4.7 [Digital] The SME banking unit has a change management framework in place that enables rapid implementation of digital, data, and AI solutions internally and for clients | E44: Does the bank have a clear change management framework or approach to ensure reliable SME digital operations? If so, what procedures are in place for implementing updates or upgrades? | F44: High | H44: High: The bank follows clear procedures for keeping SME digital services running, including service-level commitments, tools for tracking and fixing issues, and structured rollout plans for changes and updates Medium: Some practices are in place (like issue tracking or support teams), but there's no single, consistent approach Low: Support for SME digital services is mostly informal. Issues are handled on an ad hoc basis | I44: Positive, because structured change management frameworks minimize service downtime and maintain trust during system upgrades. | J44: Interview a senior leader (e.g., CIO or CTO) as well as key staff responsible for SME digital banking (e.g., Head of SME Banking or similar roles) | K44: Primary
C45: 4.7 | D45: 4.8 [Digital] New SME digital features are typically launched quickly | E45: How long does it typically take to launch a new SME digital feature from ideation to release? | F45: Low | H45: High: Most SME digital features go from concept to release in under 12 weeks, supported by short development cycles and fast approvals Medium: The typical time to launch is 3–6 months, with some internal delays or dependencies Low: Launching a new SME digital feature takes 6+ months, or timelines are unpredictable | I45: Positive, because frequent release of new digital features reflects a responsive, customer-centric innovation cycle. | J45: Interview a senior leader (e.g., CIO or CTO) as well as key staff responsible for SME digital banking (e.g., Head of SME Banking or similar roles) | K45: Primary
C46: 4.8 | D46: 4.9 [Digital] SME digital services are compliant with data privacy regulations (e.g., consent capture, data usage visibility, storage security) | E46: Are SME digital services compliant with data privacy regulations (e.g., consent capture, data usage visibility, storage security)? | F46: Yes | H46: Yes: SME digital services have consent flows, visible data use terms, and storage aligned to national/global privacy standards No: No evidence of privacy protections or regulatory alignment | I46: Positive, because compliance with privacy and security regulations is essential to maintain trust and meet legal standards. | J46: Interview a senior leader (e.g., CIO or CTO) as well as key staff responsible for SME digital banking (e.g., Head of SME Banking or similar roles) | K46: Primary
D47: 5. Products and value proposition
D48: SME offerings
...

Sheet Example 1
D4: Bank diagnostic
D5: •This sheet showcases a real-world example of the bank diagnostic in practice and provides guidance on scoring the various assessment areas and indicators. •Please note that this example is for illustrative purposes only. The scoring and rationale are based on secondary data and would likely differ significantly if complemented with primary data.
D9: Bank profile | G9: Overall standing
D10: Name: | E10: Family Bank | G10: {=_xlfn.IFS(G11<Methodology!G30,"Low maturity",G11<Methodology!G29,"Mid maturity",G11>=Methodology!G29,"High maturity")} -> #VALUE!
D11: Country of operation: | E11: Kenya | G11: {=_xlfn.LET(_xlpm.scores, _xlfn._xlws.FILTER(E19:E105, E19:E105<>""),SUMPRODUCT((_xlpm.scores="High")*Methodology!F15+(_xlpm.scores="Medium")*Methodology!F16+((_xlpm.scores="Low") + (_xlpm.scores="No data"))*Methodology!F17+(_xlpm.scores="Yes")*Methodology!I15+(_xlpm.scores="No")*Methodology!I16))} -> 102
D12: Bank type: | E12: Tier 2
D16: Criteria | E16: Score | F16: Rationale | G16: Scoring guidance | H16: Direction | I16: Assessment tips | J16: Type of source
D17: 1. Strategy
C18: # | D18: Overall strategy
C19: 1.1 | D19: 1.1 SME banking is a top priority for the bank | E19: No data | F19: This information needs to be validated with the bank's senior leadership. | G19: High: SME banking is explicitly named as one of the bank’s top 3 short-term strategic priorities Medium: SME banking is listed among the top 4–10 strategic priorities Low: SME banking is not clearly reflected among the bank's top strategic priorities or is absent from current strategy documentation | H19: Positive, given banks that consider SME programs a high priority are likely committed to their execution | I19: Interview at least two bank staff, including a senior leader (e.g., COO, CEO, or CSO), to ensure a well-rounded perspective | J19: Primary
C20: 1.2 | D20: 1.2 The targeted or current SME portfolio represents a significant share of the bank’s overall business | E20: No data | F20: This information needs to be validated with the bank's senior leadership. | G20: High: SMEs make up ≥20% of the bank’s current or targeted lending Medium: SMEs represent 10–19% of the bank’s lending Low: SMEs represent less than 10% of the bank’s lending | H20: Positive, as a high SME share of the loan book signals that SMEs are a core commercial focus, likely supported by resource allocation | I20: Interview at least two bank staff, including a senior leader (e.g., COO, CEO, or CSO), to ensure a well-rounded perspective | J20: Primary
C21: 1.3 | D21: SME strategy
C22: 1.3 | D22: 1.3 SME goals are clearly defined and time-bound | E22: High | F22: Family Bank has defined SME goals (e.g., portfolio growth, gender inclusion, and agribusiness results), but these do not have publicly available explicit KPIs and are not time-bound. | G22: High: The bank has defined SME as a distinct segment with specific and measurable goals with 3–5 year timelines, tied to planning cycles Medium: SME goals exist but are not concrete, time-bound, or lack consistent tracking and updating Low: SME-related goals are vague or aspirational, with no actionable framework | H22: Positive, as clear, time-bound SME goals that are shared across teams suggest strategic cohesion and prioritization | I22: Interview the SME Business Lead (or related positions) or a senior leader (e.g., CSO) to validate Complement with secondary information, such as annual reports and investor relations presentations | J22: Both
C23: 1.4 | D23: 1.4 SME strategy and outcomes are periodically reviewed by senior leadership | E23: Medium | F23: SME banking is overseen directly by the Board, and I assume leadership members are in charge of supervision and execution of SME strategy (this is not publicly available). | G23: High: SME operations and outcomes are closely monitored by at least one senior executive who is accountable for executing and reviewing the overall strategy on a quarterly basis Medium: SME operations are monitored but not reviewed as frequently by senior leadership (e.g., only annually) Low: No structured oversight or accountability is limited to middle management staff | H23: Positive, as periodic strategy reviews by senior leadership ensure accountability and course correction aligned with executive decision cycles | I23: Interview a senior leader (e.g., CSO or CEO) to validate | J23: Primary
C24: 1.5 | D24: 1.5 SME strategy is supported by structured, multi-year investment plans | E24: Medium | F24: The growth of Family Bank's SME segment is presented as a key priority by Family Bank's leadership. Additionally, the bank has raised significant resources from corporate bonds and DFIs (ADB) to boost SME lending. However, there are no publicly available investment plans for the medium and long term. | G24: High: The bank has defined both medium-term (1-3 year horizon) and long-term (4-6 year horizon) investment plans and allocated sufficient resources in alignment with SME goals Medium: There is an investment plan, but resource allocation or execution timelines are not as clearly defined (e.g., very long term) Low: There are no investment plans or if present these lack clear resource allocation and timelines for execution | H24: Positive, since the presence of both medium- and long-term investment plans reflects a credible roadmap and strong institutional commitment | I24: Interview a senior leader (e.g., CSO or CEO) and the SME Business Lead (or related positions) to validate Complement with internal budget documents or similar resources | J24: Primary
C25: 1.6 | D25: 1.6 SME strategy is embedded across departments and delivery channels | E25: Medium | F25: SME banking is proven to be a key pillar in Family Bank's overall operations and focus, as showcased in its annual integrated reports. This cascades into its core departments, including risk, compliance, information, and finance. | G25: High: The bank has a SME strategy that is known and reflected across core departments (e.g., credit, ops, risk, digital) and delivery teams (e.g., branches, agents, RMs). SME objectives and priorities are understood at the field level and included in branch plans Medium: SME priorities are partially reflected in support departments but weakly cascaded to delivery channels; some staff are aware, but ownership is uneven Low: There is not an SME strategy in place or there is little awareness or alignment on the SME strategy | H25: Positive, as a broad-based understanding of SME priorities across functions improves consistency in service delivery | I25: Interview the SME Business Lead (or related positions) to validate | J25: Primary
C26: 1.7 | D26: 1.7 SME impact goals have defined metrics and are consistently tracked | E26: High | F26: Family Bank focuses on women and climate-centered metrics and tracks and reports on them annually. These are overseen directly by the Board and are reviewed annually. | G26: High: Inclusion KPIs (e.g., % loans to women-led or climate-aligned SMEs) are defined, tracked, and reviewed at least annually Medium: Inclusion KPIs are defined but not tracked periodically or at the SME level Low: Inclusion KPIs are not defined or tracked throughout the organization | H26: Positive, as the regular tracking of SME impact metrics demonstrates a commitment to measuring outcomes beyond disbursements and aligned with financial inclusion | I26: Interview the SME Business Lead (or related positions) to validate Complement with secondary information, such as annual reports and investor relations presentations | J26: Both
C27: 1.8 | D27: 1.8 Proven track record delivering strategic change initiatives (e.g., product rollout, digital migration, segment launch) | E27: High | F27: Family Bank has a proven track record of delivering strategic change initiatives, including the digital transformation of the bank with solutions such as PesaPap mobile app. | G27: High: The bank has successfully implemented at least two strategic or operational initiatives in the past 3–5 years, with clear delivery outcomes and cross-functional coordination Medium: Some change initiatives were implemented but with delays, limited scale, or unclear outcomes Low: Limited or no record of executing structured change beyond business-as-usual operations | H27: Positive, since the successful delivery of change initiatives reflects strong execution, learning, and adaptation capacity, which can be leveraged to drive future SME initiatives | I27: Interview a senior leader (e.g., CSO, COO, or CEO) to validate | J27: Primary
D28: 2. Talent and organizational structure
C29: 2.1 | D29: 2.1 Dedicated SME unit with defined roles and execution responsibility | E29: High | F29: There are multiple staff members focused solely on SME across departments, including retail banking, credit & risk management, trade finance, and others. | G29: High: The bank has a full-time SME unit of at least 3–5 staff with defined roles and responsibilities across core departments (e.g., sales, credit, and product). The team has decision-making authority Medium: The bank has 1-2 designated staff members, but SME is one of many responsibilities or roles that they hold in the bank Low: No SME-specific staff or execution roles exist | H29: Positive, as the presence of a full-time, multi-functional SME team with clear responsibilities and decision-making authority indicates strong internal ownership and coordination capacity | I29: Interview a senior leader (e.g., CSO or CEO) or the SME Business Lead (or related positions) to validate Complement with secondary information, such as LinkedIn profiles and team composition on the bank's website | J29: Both
C30: 2.2 | D30: 2.2 SME staff have performance targets and incentives | E30: No data | F30: Primary information is needed to answer this question. | G30: High: SME KPIs (e.g., loan disbursement, NPLs, turnaround time, cross-sell) are embedded in the SME unit's performance evaluations, and incentives reward SME results Medium: SME KPIs exist but only for front-line or business development staff, or incentives are not sufficiently encouraging performance Low: There are no clearly defined SME KPIs or incentives | H30: Positive, as embedding SME performance metrics in team performance can reinforce strategic prioritization | I30: Interview the SME Business Lead (or related positions) to validate | J30: Primary
C31: 2.4 | D31: 2.3 Relevant trainings for SME banking are provided for relevant staff | E31: Medium | F31: Family Bank has invested in SME-related capacity building for its staff across core departments (including credit, business development, and relationship management). However, it has done this through standalone efforts instead of ongoing opportunities. | G31: High: Staff related to SME operations or strategy receive the pertinent training and have ongoing upskilling opportunities to properly execute their roles in the SME context Medium: SME specific training is not sufficiently provided, or is only provided to some staff Low: No SME-specific training or technical capacity-building is available | H31: Positive, since widespread SME-specific training ensures that staff are equipped with the knowledge and tools needed to serve the SME segment effectively | I31: Interview the SME Business Lead (or related positions) to validate | J31: Primary
D32: 3. Competitive positioning
C33: 3.1 | D33: 3.1 SME strategy is informed by market research and benchmarking | E33: High | F33: While specific market research initiatives are not detailed, the bank's targeted programs for women and youth entrepreneurs suggest a data-driven approach to identifying and serving SME segments. These are presented on annual reports. | G33: High: The bank conducts market or client research (e.g., SME segmentation studies, behavioral data, competitor market share analysis) on at least a yearly basis, and findings have influenced strategy, product design, or delivery priorities Medium: Some SME-related research exists (e.g., old market studies or internal data analysis), but is not consistently updated or has limited influence on decision-making Low: No SME-specific research has been conducted, or insights are not used to shape strategy or service design | H33: Positive, as the use of structured SME research and competitor analysis ensures better-tailored products and services and overall positioning | I33: Interview the SME Business Lead (or related positions) to validate | J33: Primary
C34: 3.2 | D34: 3.2 The bank actively identifies and targets SME segments with an uncaptured market potential | E34: High | F34: SMEs form 80% of Family Bank's customer base. It targets Agribusinesses, women-owned enterprises, and youth businesses by recognizing their unique needs in its product and service offerings. It tracks segment-specific data in its annual reports. | G34: High: The bank deliberately targets SME segments that are underserved and show clear market potential, meaning limited competition from other banks and unmet demand Medium: The bank segments and targets SMEs, but selection is not clearly based on an untapped opportunity Low: The bank serves SMEs broadly without segment-specific targeting or consideration of competitive saturation | H34: Positive, because proactive targeting of high-potential SME segments improves the bank’s ability to differentiate in competitive markets | I34: Interview the SME Business Lead (or related positions) to validate | J34: Primary
C35: 3.3 | D35: 3.3 SME competitive positioning is well-recognized across the market | E35: High | F35: Family Bank positions itself as an SME-focused institution across its public communications and strategy documents. It has been awarded Best SME Bank in Kenya and has extensive reach to SMEs through its multiple branches (95) and rural presence. | G35: High: The bank has a distinct SME brand or value proposition that is consistently communicated across channels (e.g., website, marketing, physical branches) and recognized by clients or stakeholders Medium: The bank offers SME services and may reference SMEs in its materials, but lacks a clear value proposition or consistent branding that differentiates it from competitors Low: SME offerings are not visibly positioned or promoted. There is no SME-specific branding, value proposition, or messaging | H35: Positive, as a distinct and consistently communicated SME brand or value proposition enhances market visibility and reinforces the bank’s reputation as a serious SME player | I35: Interview a senior leader (e.g., CSO or CEO) or the SME Business Lead (or related positions) to validate Complement with secondary information, such as press coverage, award recognitions, and social media campaigns | J35: Secondary
C36: 3.4 | D36: 3.4 [Digital] The value proposition of SME banking is enhanced by data analytics and digital innovation | E36: No data | F36: Primary information is needed to answer this question. | G36: High: The SME value proposition is regularly enhanced through the use of data analytics or digital innovation (e.g., automated onboarding, digital credit scoring). These tools are actively used to shape SME product development or service delivery Medium: Some SME initiatives are informed by data or enhanced through digital strategies, but this is applied inconsistently or on a limited basis Low: SME offerings are rarely or never shaped by data analytics or digital tools | H36: Positive, as basing initiatives on market analyses ensures relevance, enhances SME uptake, and supports value-driven innovation. | I36: Interview a senior leader (e.g., CIO or CTO) as well as key staff responsible for SME digital banking (e.g., Head of SME Banking or similar roles) | J36: Primary
D37: 4. Operational processes
C38: 4.1 | D38: 4.1 SME credit processes are flexible and adapted to typical access-to-finance constraints and priorities of SMEs | E38: High | F38: Family Bank has tailored processes that recognize SME possibilities. For example, it uses cash-flow-based credit assessment models backed with insurance to lend to smallholder farmers. It also offers flexible collateral requirements to accommodate SME needs. | G38: High: Credit assessment processes are meaningfully adapted to SME realities (e.g., cash-flow-based analysis, flexible collateral, data-driven models) and are consistently applied by staff handling SME lending Medium: Some SME-appropriate credit practices exist but are applied inconsistently or are not institutionalized Low: SME credit follows standard corporate models with no tailored features | H38: Positive, because when the bank’s credit processes are meaningfully tailored to SME realities, financial products can be offered more safely and inclusively to a broader SME customer base | I38: Interview the SME Business Lead (or related positions) or other internal experts (e.g., Head of Credit or Head of Risk) to validate | J38: Primary
C39: 4.2 | D39: 4.2 Segmentation drives the design and tailoring of products and services | E39: High | F39: Family Bank focuses on specific SME segments, including agribusiness, women, and even Chinese-owned SMEs. Limited information on how frequently these segments are updated. | G39: High: SME segments are well-defined (e.g., by size, lifecycle, sector) and actively shape product or service design (e.g., pricing, bundling, distribution). Segmentation is regularly reviewed and updated Medium: Key SME segments are identified but used only superficially in some aspects of product and service design Low: There is no clear SME segmentation, or segmentation exists but has no influence on product or service decisions | H39: Positive, as the use of clearly defined SME segments to shape product, pricing, and delivery strategies enables more relevant and effective offerings across client types | I39: Interview the SME Business Lead (or related positions) or other internal experts (e.g., Product Manager) to validate | J39: Primary
C40: 4.3 | D40: 4.3 Relationship managers deliver tailored engagement to SMEs | E40: High | F40: Family Bank uses a relationship management model that offers end-to-end support. Relationship managers are usually assigned to specific SME segments or sectors. The bank implements CRM practices to enhance service quality and customer relations. | G40: High: Relationship managers or account officers are assigned to SME clients with defined portfolios and use structured engagement tools (e.g., CRM systems) Medium: There are SME focused staff who engage clients, but there are no consistent or standardized engagement practices Low: There is no relationship management model for SMEs, or interactions are reactive or handled by generalist staff | H40: Positive, since assigning relationship managers with dedicated SME portfolios ensures more consistent and targeted support that helps deepen long-term client relationships | I40: Interview the SME Business Lead (or related positions) or other internal experts (e.g., Lead Engagement Manager) to validate | J40: Primary
