Workbook
Name Choice: '[1]Lists (2)'!$B$5:$B$7
Name CodeCountries: [2]Lists!$C$212:$C$242
Name CodeCountries: [1]Lists!$C$212:$C$242
Name country: '[3]Pull-down menus'!$C$38:$C$236
Name Input: [2]Lists!$C$6:$C$7
Name Input: [1]Lists!$C$6:$C$7
Name Type: [2]Lists!$C$247:$C$248
Name Type: [1]Lists!$C$247:$C$248
Name YesNo: [2]Lists!$C$252:$C$253
Name YesNo: [1]Lists!$C$252:$C$253

Sheet Instructions & Overview
I5: Business Case Tool
I6: INVEST: The Process & Toolkit for Unleashing SME Banking
D11: Last modified: June XX, 2025
D13: OVERVIEW
D15: The Business Case Tool is an Excel-based diagnostic designed to help commercial banks estimate the return they could expect on their SME banking expansion. It ties in with the market sizing tool, a data-driven summary of over 160 markets, and combines the specific cost and revenue drivers of the institution to evaluate the upfront costs, overall returns, break even points and cash flow over a 7-year horizon. The tool relies on assessments made by the user in order to best align with the prevaling market conditions, various strategy options and the policies pursued by the institution for which the user is making their assessment.
D18: Focus audience:
D19: USE CASE
D21: The tool allows users to formulate a goal and a combination of strategies for achieving it, and assess: 1) Total investment requirements, 2) Total returns, 3) Profit and cash flows, and 4) Operational indicators. It supports confident strategy formulation and prioritization by estimating the outcomes each approach would deliver over the medium-term. Please note that despite the 7-year horizon, the model calculates the figures in current real terms, since the financial institutions it is being used for could adopt different policies to control for macroeconomic factors such as inflation and wage growth and are the best suited to foresee how these factors might influence their local economy in the medium term.
D25: OBJECTIVES
D27: 1. Provide a quick and intuitive assessment of the revenue potential of an expansion into the SME segment. 2. Enable users to assess the feasibility of their objectives and adjust them to target the optimal outcome. 3. Support evidence-based decision-making for SME banking expansion in their market.
D31: GUIDANCE
D33: This file consists of seven tabs, including this one. Below is a high-level description of each tab, along with specific instructions on how users can interact with them to leverage the tool succesfully.
D36: Tab Name | F36: Description | AK36: Instructions | AM36: Instructions
D38: Assumptions | F38: This tab allows the user to set their targets and insert the conditions under which they would operate in order to achieve those targets and to set alternative values to run a sensitivity analysis on the factors laid out in the model. | AM38: Insert the conditions under which you want to model the scenario.
D40: Outputs overview | F40: This tab highlights the most important outcomes determining the feasibility of the expansion and provides a visual representation of the progression of the project. | AM40: Review key outputs for your primary scenario.
D42: Sensitivity analysis | F42: This tab follows the layout of the "Outputs overview" but highlights the differences in the outcomes resulting from the sensitivity analysis. | AM42: Review differences in key outputs between your primary and comparison scenarios.
D44: Key financial and ops fig.s LCY | F44: This sheet gives detailed figures on the financial outcomes and operating parameters of the project on a quarterly and annual level over a 7-year horizon. | AM44: -
D46: Alt. scenario LCY | F46: This sheet gives the same figures as the previous sheet for the alternative scenario that the sensitivity analysis is based on. | AM46: -
D48: Key financial and ops fig.s COM | F48: Since it is common practice, especially in smaller markets where the local currency is weak or unstable, to assess major projects in a foreign currency, like reserve currencies, this sheet provides an overview of the same numbers as the previous sheet presented in a second currency of the user's choosing. | AM48: -
D50: Alt. scenario COM | F50: This sheet gives the same figures as the previous sheet for the alternative scenario that the sensitivity analysis is based on. | AM50: -
D52: All scenarios | F52: This sheet consolidates the figures from the previous four sheets and provides a side by side comparison. | AM52: If you would like to view the individual scenarios in a single sheet, go straight to this sheet.
D54: Baseline Headcount Estimate | F54: This tab contains an extract from the related Market Sizing Tool to enable this tool to estimate the project's market share and feasibility of the user's targets within the wider context of the selected market. | AM54: -
D56: Lists | F56: Location of Pull-Down lists used in this model | AM56: -
D59: USING THIS TOOL EFFECTIVELY
D61: This tool is designed for a wide range of users—including TA funders, commercial banks, and ecosystem enablers—who want to assess the feasibility and the expected returns of a push for expansion in the SME sector using various combinations of strategies.
D64: The tool provides a strong foundation for project assessment. Users can set their targets, align parameters with the existing conditions under which they operate or the conditions they strive for, the tool provides an assessment of the bank's readiness and opportunity for SME banking.
D68: LINKS TO USER GUIDE AND VIDEO TUTORIAL
K69: Move to the next sheet to begin screening potential partner banks and identifying the most suitable candidates!
D71: User Guide: | E71: [insert link]
D73: Video tutorial: | E73: [insert link]

Sheet Assumptions
C2: Business Case Tool
C3: Please only fill in the orange cells in columns D and G. If your selections render any other fields unnecessary, they will automatically be blacked out.
B5: Please select your country | D5: Albania | E5: Please select the country for which you want to use the tool from the drop-down menu
C6: Local currency | D6: ALL | E6: Please enter the local currency of the country for which you want to use the tool. Please note that all inputs should be done in the local currency.
C7: Rounding (local currency) | D7: no rounding | E7: Please select if you want the results displayed in full amounts, thousands, millions or billions of local currency
C8: Comparison currency | D8: USD | E8: If you want to see the results modelled in a second currency, please insert that currency here. Please note that the compariosn currency is for illustrative purposes only. Inputs in the model should be done in local currency.
C9: Rounding (comparison currency) | D9: no rounding | E9: Please select if you want the results displayed in full amounts, thousands, millions or billions of comparison currency
C10: Exchange rate | D10: 0.012 | E10: Please insert the exchange rate between the two currencies (in a format of one unit of local currency to one unit in comparison currency)
B11: Target share of market captured by sector | F11: Captured share of overall market | G11: Values for sensitivity analysis Overwrite cells where you want to compare with different values from column D
C12: - medium | D12: 200 | E12: Please insert the target number of clients in this sector you would like to achieve | F12: =IFERROR(Assumptions!D12/(_xlfn.XLOOKUP(Assumptions!$D$5, 'Baseline Headcount Estimates'!$B$13:$B$180, 'Baseline Headcount Estimates'!$R$13:$R$180, "")*1000), "N/A") -> 0.070294779 | G12: =D12 -> 200 | H12: =IFERROR(Assumptions!G12/(_xlfn.XLOOKUP(Assumptions!$D$5, 'Baseline Headcount Estimates'!$B$13:$B$180, 'Baseline Headcount Estimates'!$R$13:$R$180, "")*1000), "N/A") -> 0.070294779 | I12: =IF(F12>1,"TARGET EXCEEDS TOTAL MARKET","") | J12: =IF(H12>1,"TARGET EXCEEDS TOTAL MARKET","")
C13: - small | D13: 1000 | E13: Please insert the target number of clients in this sector you would like to achieve | F13: =IFERROR(Assumptions!D13/(_xlfn.XLOOKUP(Assumptions!$D$5, 'Baseline Headcount Estimates'!$B$13:$B$180, 'Baseline Headcount Estimates'!$Q$13:$Q$180, "")*1000), "N/A") -> 0.12018056 | G13: =D13 -> 1000 | H13: =IFERROR(Assumptions!G13/(_xlfn.XLOOKUP(Assumptions!$D$5, 'Baseline Headcount Estimates'!$B$13:$B$180, 'Baseline Headcount Estimates'!$Q$13:$Q$180, "")*1000), "N/A") -> 0.12018056 | I13: =IF(F13>1,"TARGET EXCEEDS TOTAL MARKET","") | J13: =IF(H13>1,"TARGET EXCEEDS TOTAL MARKET","")
C14: - very small | D14: 5000 | E14: Please insert the target number of clients in this sector you would like to achieve | F14: =IFERROR(Assumptions!D14/(_xlfn.XLOOKUP(Assumptions!$D$5, 'Baseline Headcount Estimates'!$B$13:$B$180, 'Baseline Headcount Estimates'!$P$13:$P$180, "")*1000), "N/A") -> 0.19759702 | G14: =D14 -> 5000 | H14: =IFERROR(Assumptions!G14/(_xlfn.XLOOKUP(Assumptions!$D$5, 'Baseline Headcount Estimates'!$B$13:$B$180, 'Baseline Headcount Estimates'!$P$13:$P$180, "")*1000), "N/A") -> 0.19759702 | I14: =IF(F14>1,"TARGET EXCEEDS TOTAL MARKET","") | J14: =IF(H14>1,"TARGET EXCEEDS TOTAL MARKET","")
C15: - self-employed and micro | D15: 40000 | E15: Please insert the target number of clients in this sector you would like to achieve | F15: =IFERROR(Assumptions!D15/(_xlfn.XLOOKUP(Assumptions!$D$5, 'Baseline Headcount Estimates'!$B$13:$B$180, 'Baseline Headcount Estimates'!$O$13:$O$180, "")*1000), "N/A") -> 0.19002391 | G15: =D15 -> 40000 | H15: =IFERROR(Assumptions!G15/(_xlfn.XLOOKUP(Assumptions!$D$5, 'Baseline Headcount Estimates'!$B$13:$B$180, 'Baseline Headcount Estimates'!$O$13:$O$180, "")*1000), "N/A") -> 0.19002391 | I15: =IF(F15>1,"TARGET EXCEEDS TOTAL MARKET","") | J15: =IF(H15>1,"TARGET EXCEEDS TOTAL MARKET","")
C16: Target timeline for acquisition of new clients | D16: 5 | E16: Please insert the time (in years, between 1 and 5) in which you would like to achieve the targets set out above | G16: =D16 -> 5
C17: Share of electronic banking | D17: 0.5 | E17: Please insert the share of your clients that do their banking primarily online | G17: =D17 -> 0.5
B18: Interest rates and fees
C19: Interest rate on business loans | D19: 0.05 | E19: Please insert the average interest rate on business loans that your institution charges clients | G19: =D19 -> 0.05
C20: Interest rate on mortgages | D20: 0.035 | E20: Please insert the average interest rate on mortgage-backed home loans that your institution charges clients | G20: =D20 -> 0.035
C21: Interest rate on autoloans | D21: 0.08 | E21: Please insert the average interest rate on autoloans that your institution charges clients | G21: =D21 -> 0.08
C22: Interest rate on deposits | D22: 0.015 | E22: Please insert the average interest rate on savings and long-term deposits that your institution pays clients | G22: =D22 -> 0.015
C23: Refinancing rate | D23: 0.02 | E23: Please insert the average refinancing rate of the local financial market | G23: =D23 -> 0.02
C24: Account maintenance fee | D24: 0 | E24: Please insert average account maintenance fee as % of average account balance. If no such fee is charged, insert 0 | G24: =D24 -> 0
C25: Interest rate on checking accounts | D25: 0.005 | E25: Please insert the average interest rate paid to clients for balances in their checking accounts. If no such interest rate is paid, insert 0 | G25: =D25 -> 0.005
C26: Transaction fees (intrabank) | D26: 0.002 | E26: Please insert the transaction fees (as % of the transaction amount) charged to clients for transactions made to other acounts in your institution for a payment order submitted in person in a bank branch | G26: =D26 -> 0.002
C27: Transaction fees e-banking (intrabank) | D27: =D26/2 -> 0.001 | E27: Please insert the transaction fees (as % of the transaction amount) charged to clients for transactions made to other acounts in your institution for a payment order submitted through electronic banking | G27: =D27 -> 0.001
C28: Transaction fees (interbank) | D28: 0.005 | E28: Please insert the transaction fees (as % of the transaction amount) charged to clients for transactions made to acounts in another financial institution less fees payable to intermediaries and receiving institution for a payment order submitted in person in a bank branch | G28: =D28 -> 0.005
C29: Transaction fees e-banking (interbank) | D29: =D28/2 -> 0.0025 | E29: Please insert the transaction fees (as % of the transaction amount) charged to clients for transactions made to acounts in another financial institution less fees payable to intermediaries and receiving institution for a payment order submitted through electronic banking | G29: =D29 -> 0.0025
C30: Transaction fees (international) | D30: 0.01 | E30: Please insert the transaction fees (as % of the transaction amount) charged to clients for international transactions less fees payable to intermediaries and receiving institution for a payment order submitted in person in a bank branch | G30: =D30 -> 0.01
C31: Transaction fees e-banking (international) | D31: =D30/2 -> 0.005 | E31: Please insert the transaction fees (as % of the transaction amount) charged to clients for international transactions less fees payable to intermediaries and receiving institution for a payment order submitted through electronic banking | G31: =D31 -> 0.005
C32: Loan processing fee | D32: 0.01 | E32: Please insert the fee (as % of loan amount) charged for processing loans | G32: =D32 -> 0.01
B33: Services | F33: In comparison currency (if applicable)
C34: NPL | D34: 0.01 | E34: Please insert the proportion of loans written down annually as non-performing | G34: =D34 -> 0.01
C35: Reserve requirement | D35: 0.1 | E35: Please insert the minimum reserve rate mandated by the central bank | G35: =D35 -> 0.1
C36: Interest earned on minimum reserves | D36: 0.01 | E36: If the central bank pays any interest on the reserves, please insert the interest rate here. Otherwise, insert 0 | G36: =D36 -> 0.01
C37: Average business loan volume for medium enterprises | D37: 100000000 | E37: Please insert the average loan volume outstanding for a company in this sector with your institution | F37: =D37*$D$10 -> 1200000 | G37: =D37 -> 100000000 | H37: =G37*$D$10 -> 1200000
C38: Average business loan volume for small enterprises | D38: 10000000 | E38: Please insert the average loan volume outstanding for a company in this sector with your institution | F38: =D38*$D$10 -> 120000 | G38: =D38 -> 10000000 | H38: =G38*$D$10 -> 120000
C39: Average business loan volume for very small enterprises | D39: 2500000 | E39: Please insert the average loan volume outstanding for a company in this sector with your institution | F39: =D39*$D$10 -> 30000 | G39: =D39 -> 2500000 | H39: =G39*$D$10 -> 30000
C40: Average business loan volume for micro enterprises and self employed entrepreneurs | D40: 500000 | E40: Please insert the average loan volume outstanding for a company in this sector with your institution | F40: =D40*$D$10 -> 6000 | G40: =D40 -> 500000 | H40: =G40*$D$10 -> 6000
C41: Average business loan uptake for medium enterprises | D41: 0.4 | E41: Please insert the proportion of companies in this sector that have loans outstanding with your institution | G41: =D41 -> 0.4
C42: Average business loan uptake for small enterprises | D42: 0.4 | E42: Please insert the proportion of companies in this sector that have loans outstanding with your institution | G42: =D42 -> 0.4
...

Sheet Outputs overview 
C2: Business Case Tool
C3: =IF(Assumptions!D7<>Lists!B2,CONCATENATE("Outputs overview- ",Assumptions!D7," of ",Assumptions!D6),CONCATENATE("Outputs overview- in ",Assumptions!D6)) -> Outputs overview- in ALL
C5: =CONCATENATE("TOTAL INVESTMENT (",Assumptions!D6,")") -> TOTAL INVESTMENT (ALL) | D5: =-('Key financial and ops fig.s LCY'!H58+'Key financial and ops fig.s LCY'!M58+'Key financial and ops fig.s LCY'!R58+'Key financial and ops fig.s LCY'!W58+'Key financial and ops fig.s LCY'!AG58+'Key financial and ops fig.s LCY'!AL58) -> 433850000
C6: =CONCATENATE("TOTAL INVESTMENT (",Assumptions!D8,")") -> TOTAL INVESTMENT (USD) | D6: =D5*Assumptions!D10 -> 5206200
C7: =CONCATENATE("TOTAL NET INCOME (",Assumptions!D6,") OVER 7-YEAR PERIOD") -> TOTAL NET INCOME (ALL) OVER 7-YEAR PERIOD | D7: ='Key financial and ops fig.s LCY'!AL49 -> 7.322392e+09
C8: =CONCATENATE("TOTAL NET INCOME (",Assumptions!D8,") OVER 7-YEAR PERIOD") -> TOTAL NET INCOME (USD) OVER 7-YEAR PERIOD | D8: =D7*Assumptions!D10 -> 87868704
C9: ABSOLUTE ROI | D9: =D7/D5 -> 16.877704
C10: ANNUALIZED ROI | D10: =D9/7 -> 2.4111006
C12: BREAK EVEN | D12: {=INDEX('Key financial and ops fig.s LCY'!D5:AL5, MATCH(TRUE, 'Key financial and ops fig.s LCY'!D49:AL49>0, 0))} -> Y2
C13: FIRST PROFITABLE QUARTER | D13: {=INDEX('Key financial and ops fig.s LCY'!D5:AL5, MATCH(TRUE, 'Key financial and ops fig.s LCY'!D45:AL45>0, 0))} -> Q3 Y1
C14: REPAYMENT OF INVESTMENT | D14: {=INDEX('Key financial and ops fig.s LCY'!D5:AL5, MATCH(TRUE, 'Key financial and ops fig.s LCY'!D61:AL61>0, 0))} -> Q2 Y3

Sheet Sensitivity analysis
C2: Business Case Tool
C3: =IF(Assumptions!D7<>Lists!B2,CONCATENATE("Outputs overview- ",Assumptions!D7," of ",Assumptions!D6),CONCATENATE("Outputs overview- in ",Assumptions!D6)) -> Outputs overview- in ALL
D4: Base scenario | E4: Alternative scenario | F4: Difference
C5: =CONCATENATE("TOTAL INVESTMENT (",Assumptions!D6,")") -> TOTAL INVESTMENT (ALL) | D5: =-('Key financial and ops fig.s LCY'!H58+'Key financial and ops fig.s LCY'!M58+'Key financial and ops fig.s LCY'!R58+'Key financial and ops fig.s LCY'!W58+'Key financial and ops fig.s LCY'!AG58+'Key financial and ops fig.s LCY'!AL58) -> 433850000 | E5: =-('Alt. scenario LCY'!H58+'Alt. scenario LCY'!M58+'Alt. scenario LCY'!R58+'Alt. scenario LCY'!W58+'Alt. scenario LCY'!AG58+'Alt. scenario LCY'!AL58) -> 433850000 | F5: =E5-D5 -> 0
C6: =CONCATENATE("TOTAL INVESTMENT (",Assumptions!D8,")") -> TOTAL INVESTMENT (USD) | D6: =D5*Assumptions!D10 -> 5206200 | E6: =E5*Assumptions!D10 -> 5206200 | F6: =E6-D6 -> 0
C7: =CONCATENATE("TOTAL NET INCOME (",Assumptions!D6,") OVER 7-YEAR PERIOD") -> TOTAL NET INCOME (ALL) OVER 7-YEAR PERIOD | D7: ='Key financial and ops fig.s LCY'!AL49 -> 7.322392e+09 | E7: ='Alt. scenario LCY'!AL49 -> 7.322392e+09 | F7: =E7-D7 -> 0
C8: =CONCATENATE("TOTAL NET INCOME (",Assumptions!D8,") OVER 7-YEAR PERIOD") -> TOTAL NET INCOME (USD) OVER 7-YEAR PERIOD | D8: =D7*Assumptions!D10 -> 87868704 | E8: =E7*Assumptions!D10 -> 87868704 | F8: =E8-D8 -> 0
C9: ABSOLUTE ROI | D9: =D7/D5 -> 16.877704 | E9: =E7/E5 -> 16.877704 | F9: =E9-D9 -> 0
C10: ANNUALIZED ROI | D10: =D9/7 -> 2.4111006 | E10: =E9/7 -> 2.4111006 | F10: =E10-D10 -> 0
C12: BREAK EVEN | D12: {=INDEX('Key financial and ops fig.s LCY'!D5:AL5, MATCH(TRUE, 'Key financial and ops fig.s LCY'!D49:AL49>0, 0))} -> Y2 | E12: {=INDEX('Alt. scenario LCY'!D5:AL5, MATCH(TRUE, 'Alt. scenario LCY'!D49:AL49>0, 0))} -> Y2 | F12: =IF(E12<>D12,"DIFFERENT PERIOD","")
C13: FIRST PROFITABLE QUARTER | D13: {=INDEX('Key financial and ops fig.s LCY'!D5:AL5, MATCH(TRUE, 'Key financial and ops fig.s LCY'!D45:AL45>0, 0))} -> Q3 Y1 | E13: {=INDEX('Alt. scenario LCY'!D5:AL5, MATCH(TRUE, 'Alt. scenario LCY'!D45:AL45>0, 0))} -> Q3 Y1 | F13: =IF(E13<>D13,"DIFFERENT PERIOD","")
C14: REPAYMENT OF INVESTMENT | D14: {=INDEX('Key financial and ops fig.s LCY'!D5:AL5, MATCH(TRUE, 'Key financial and ops fig.s LCY'!D61:AL61>0, 0))} -> Q2 Y3 | E14: {=INDEX('Alt. scenario LCY'!D5:AL5, MATCH(TRUE, 'Alt. scenario LCY'!D61:AL61>0, 0))} -> Q2 Y3 | F14: =IF(E14<>D14,"DIFFERENT PERIOD","")
K83: .

Sheet Key financial and ops fig.s LCY
C2: Business Case Tool
C3: =IF(Assumptions!D7<>Lists!B2,CONCATENATE("Modelled outputs- ",Assumptions!D7," of ",Assumptions!D6),CONCATENATE("Modelled outputs- in ",Assumptions!D6)) -> Modelled outputs- in ALL
A5: INCOME STATEMENT | D5: Q1 Y1 | E5: Q2 Y1 | F5: Q3 Y1 | G5: Q4 Y1 | H5: Y1 | I5: Q1 Y2 | J5: Q2 Y2 | K5: Q3 Y2 | L5: Q4 Y2 | M5: Y2 | N5: Q1 Y3 | O5: Q2 Y3 | P5: Q3 Y3 | Q5: Q4 Y3 | R5: Y3 | S5: Q1 Y4 | T5: Q2 Y4 | U5: Q3 Y4 | V5: Q4 Y4 | W5: Y4 | X5: Q1 Y5 | Y5: Q2 Y5 | Z5: Q3 Y5 | AA5: Q4 Y5 | AB5: Y5 | AC5: Q1 Y6 | AD5: Q2 Y6 | AE5: Q3 Y6 | AF5: Q4 Y6 | AG5: Y6 | AH5: Q1 Y7 | AI5: Q2 Y7 | AJ5: Q3 Y7 | AK5: Q4 Y7 | AL5: Y7
C6: Net interest income on business loans | D6: =D76*(Assumptions!$D$19-Assumptions!$D$23)/4 -> 9316406.2 | E6: =E76*(Assumptions!$D$19-Assumptions!$D$23)/4 -> 18515625 | F6: =F76*(Assumptions!$D$19-Assumptions!$D$23)/4 -> 27597656 | G6: =G76*(Assumptions!$D$19-Assumptions!$D$23)/4 -> 36562500 | H6: =SUM(D6:G6) -> 91992188 | I6: =I76*(Assumptions!$D$19-Assumptions!$D$23)/4 -> 45410156 | J6: =J76*(Assumptions!$D$19-Assumptions!$D$23)/4 -> 54140625 | K6: =K76*(Assumptions!$D$19-Assumptions!$D$23)/4 -> 62753906 | L6: =L76*(Assumptions!$D$19-Assumptions!$D$23)/4 -> 71250000 | M6: =SUM(I6:L6) -> 2.3355469e+08 | N6: =N76*(Assumptions!$D$19-Assumptions!$D$23)/4 -> 79628906 | O6: =O76*(Assumptions!$D$19-Assumptions!$D$23)/4 -> 87890625 | P6: =P76*(Assumptions!$D$19-Assumptions!$D$23)/4 -> 96035156 | Q6: =Q76*(Assumptions!$D$19-Assumptions!$D$23)/4 -> 1.040625e+08 | R6: =SUM(N6:Q6) -> 3.6761719e+08 | S6: =S76*(Assumptions!$D$19-Assumptions!$D$23)/4 -> 1.1197266e+08 | T6: =T76*(Assumptions!$D$19-Assumptions!$D$23)/4 -> 1.1976563e+08 | U6: =U76*(Assumptions!$D$19-Assumptions!$D$23)/4 -> 1.2744141e+08 | V6: =V76*(Assumptions!$D$19-Assumptions!$D$23)/4 -> 135000000 | W6: =SUM(S6:V6) -> 4.9417969e+08 | X6: =X76*(Assumptions!$D$19-Assumptions!$D$23)/4 -> 1.4244141e+08 | Y6: =Y76*(Assumptions!$D$19-Assumptions!$D$23)/4 -> 149765625 | Z6: =Z76*(Assumptions!$D$19-Assumptions!$D$23)/4 -> 1.5697266e+08 | AA6: =AA76*(Assumptions!$D$19-Assumptions!$D$23)/4 -> 164062500 | AB6: =SUM(X6:AA6) -> 6.1324219e+08 | AC6: =AC76*(Assumptions!$D$19-Assumptions!$D$23)/4 -> 162890625 | AD6: =AD76*(Assumptions!$D$19-Assumptions!$D$23)/4 -> 161718750 | AE6: =AE76*(Assumptions!$D$19-Assumptions!$D$23)/4 -> 160546875 | AF6: =AF76*(Assumptions!$D$19-Assumptions!$D$23)/4 -> 159375000 | AG6: =SUM(AC6:AF6) -> 644531250 | AH6: =AH76*(Assumptions!$D$19-Assumptions!$D$23)/4 -> 158203125 | AI6: =AI76*(Assumptions!$D$19-Assumptions!$D$23)/4 -> 157031250 | AJ6: =AJ76*(Assumptions!$D$19-Assumptions!$D$23)/4 -> 155859375 | AK6: =AK76*(Assumptions!$D$19-Assumptions!$D$23)/4 -> 154687500 | AL6: =SUM(AH6:AK6) -> 625781250
C7: Net interest income on mortgages | D7: =D77*(Assumptions!$D$20-Assumptions!$D$23)/4 -> 4304179.7 | E7: =E77*(Assumptions!$D$20-Assumptions!$D$23)/4 -> 8554218.8 | F7: =F77*(Assumptions!$D$20-Assumptions!$D$23)/4 -> 12750117 | G7: =G77*(Assumptions!$D$20-Assumptions!$D$23)/4 -> 16891875 | H7: =SUM(D7:G7) -> 42500391 | I7: =I77*(Assumptions!$D$20-Assumptions!$D$23)/4 -> 20979492 | J7: =J77*(Assumptions!$D$20-Assumptions!$D$23)/4 -> 25012969 | K7: =K77*(Assumptions!$D$20-Assumptions!$D$23)/4 -> 28992305 | L7: =L77*(Assumptions!$D$20-Assumptions!$D$23)/4 -> 32917500 | M7: =SUM(I7:L7) -> 1.0790227e+08 | N7: =N77*(Assumptions!$D$20-Assumptions!$D$23)/4 -> 36788555 | O7: =O77*(Assumptions!$D$20-Assumptions!$D$23)/4 -> 40605469 | P7: =P77*(Assumptions!$D$20-Assumptions!$D$23)/4 -> 44368242 | Q7: =Q77*(Assumptions!$D$20-Assumptions!$D$23)/4 -> 48076875 | R7: =SUM(N7:Q7) -> 1.6983914e+08 | S7: =S77*(Assumptions!$D$20-Assumptions!$D$23)/4 -> 51731367 | T7: =T77*(Assumptions!$D$20-Assumptions!$D$23)/4 -> 55331719 | U7: =U77*(Assumptions!$D$20-Assumptions!$D$23)/4 -> 58877930 | V7: =V77*(Assumptions!$D$20-Assumptions!$D$23)/4 -> 62370000 | W7: =SUM(S7:V7) -> 2.2831102e+08 | X7: =X77*(Assumptions!$D$20-Assumptions!$D$23)/4 -> 65807930 | Y7: =Y77*(Assumptions!$D$20-Assumptions!$D$23)/4 -> 69191719 | Z7: =Z77*(Assumptions!$D$20-Assumptions!$D$23)/4 -> 72521367 | AA7: =AA77*(Assumptions!$D$20-Assumptions!$D$23)/4 -> 75796875 | AB7: =SUM(X7:AA7) -> 2.8331789e+08 | AC7: =AC77*(Assumptions!$D$20-Assumptions!$D$23)/4 -> 75255469 | AD7: =AD77*(Assumptions!$D$20-Assumptions!$D$23)/4 -> 74714063 | AE7: =AE77*(Assumptions!$D$20-Assumptions!$D$23)/4 -> 74172656 | AF7: =AF77*(Assumptions!$D$20-Assumptions!$D$23)/4 -> 73631250 | AG7: =SUM(AC7:AF7) -> 2.9777344e+08 | AH7: =AH77*(Assumptions!$D$20-Assumptions!$D$23)/4 -> 73089844 | AI7: =AI77*(Assumptions!$D$20-Assumptions!$D$23)/4 -> 72548438 | AJ7: =AJ77*(Assumptions!$D$20-Assumptions!$D$23)/4 -> 72007031 | AK7: =AK77*(Assumptions!$D$20-Assumptions!$D$23)/4 -> 71465625 | AL7: =SUM(AH7:AK7) -> 2.8911094e+08
C8: Net interest income on auto loans and leasing | D8: =D78*(Assumptions!$D$21-Assumptions!$D$23)/4 -> 1721671.9 | E8: =E78*(Assumptions!$D$21-Assumptions!$D$23)/4 -> 3421687.5 | F8: =F78*(Assumptions!$D$21-Assumptions!$D$23)/4 -> 5100046.9 | G8: =G78*(Assumptions!$D$21-Assumptions!$D$23)/4 -> 6756750 | H8: =SUM(D8:G8) -> 17000156 | I8: =I78*(Assumptions!$D$21-Assumptions!$D$23)/4 -> 8391796.9 | J8: =J78*(Assumptions!$D$21-Assumptions!$D$23)/4 -> 10005188 | K8: =K78*(Assumptions!$D$21-Assumptions!$D$23)/4 -> 11596922 | L8: =L78*(Assumptions!$D$21-Assumptions!$D$23)/4 -> 13167000 | M8: =SUM(I8:L8) -> 43160906 | N8: =N78*(Assumptions!$D$21-Assumptions!$D$23)/4 -> 14715422 | O8: =O78*(Assumptions!$D$21-Assumptions!$D$23)/4 -> 16242188 | P8: =P78*(Assumptions!$D$21-Assumptions!$D$23)/4 -> 17747297 | Q8: =Q78*(Assumptions!$D$21-Assumptions!$D$23)/4 -> 19230750 | R8: =SUM(N8:Q8) -> 67935656 | S8: =S78*(Assumptions!$D$21-Assumptions!$D$23)/4 -> 20692547 | T8: =T78*(Assumptions!$D$21-Assumptions!$D$23)/4 -> 22132688 | U8: =U78*(Assumptions!$D$21-Assumptions!$D$23)/4 -> 23551172 | V8: =V78*(Assumptions!$D$21-Assumptions!$D$23)/4 -> 24948000 | W8: =SUM(S8:V8) -> 91324406 | X8: =X78*(Assumptions!$D$21-Assumptions!$D$23)/4 -> 26323172 | Y8: =Y78*(Assumptions!$D$21-Assumptions!$D$23)/4 -> 27676688 | Z8: =Z78*(Assumptions!$D$21-Assumptions!$D$23)/4 -> 29008547 | AA8: =AA78*(Assumptions!$D$21-Assumptions!$D$23)/4 -> 30318750 | AB8: =SUM(X8:AA8) -> 1.1332716e+08 | AC8: =AC78*(Assumptions!$D$21-Assumptions!$D$23)/4 -> 30102188 | AD8: =AD78*(Assumptions!$D$21-Assumptions!$D$23)/4 -> 29885625 | AE8: =AE78*(Assumptions!$D$21-Assumptions!$D$23)/4 -> 29669062 | AF8: =AF78*(Assumptions!$D$21-Assumptions!$D$23)/4 -> 29452500 | AG8: =SUM(AC8:AF8) -> 119109375 | AH8: =AH78*(Assumptions!$D$21-Assumptions!$D$23)/4 -> 29235938 | AI8: =AI78*(Assumptions!$D$21-Assumptions!$D$23)/4 -> 29019375 | AJ8: =AJ78*(Assumptions!$D$21-Assumptions!$D$23)/4 -> 28802812 | AK8: =AK78*(Assumptions!$D$21-Assumptions!$D$23)/4 -> 28586250 | AL8: =SUM(AH8:AK8) -> 115644375
C9: Net interest income on deposits | D9: =D79*(Assumptions!$D$23-Assumptions!$D$22)/4 -> 143472.66 | E9: =E79*(Assumptions!$D$23-Assumptions!$D$22)/4 -> 285140.63 | F9: =F79*(Assumptions!$D$23-Assumptions!$D$22)/4 -> 425003.91 | G9: =G79*(Assumptions!$D$23-Assumptions!$D$22)/4 -> 563062.5 | H9: =SUM(D9:G9) -> 1416679.7 | I9: =I79*(Assumptions!$D$23-Assumptions!$D$22)/4 -> 699316.41 | J9: =J79*(Assumptions!$D$23-Assumptions!$D$22)/4 -> 833765.63 | K9: =K79*(Assumptions!$D$23-Assumptions!$D$22)/4 -> 966410.16 | L9: =L79*(Assumptions!$D$23-Assumptions!$D$22)/4 -> 1097250 | M9: =SUM(I9:L9) -> 3596742.2 | N9: =N79*(Assumptions!$D$23-Assumptions!$D$22)/4 -> 1226285.2 | O9: =O79*(Assumptions!$D$23-Assumptions!$D$22)/4 -> 1353515.6 | P9: =P79*(Assumptions!$D$23-Assumptions!$D$22)/4 -> 1478941.4 | Q9: =Q79*(Assumptions!$D$23-Assumptions!$D$22)/4 -> 1602562.5 | R9: =SUM(N9:Q9) -> 5661304.7 | S9: =S79*(Assumptions!$D$23-Assumptions!$D$22)/4 -> 1724378.9 | T9: =T79*(Assumptions!$D$23-Assumptions!$D$22)/4 -> 1844390.6 | U9: =U79*(Assumptions!$D$23-Assumptions!$D$22)/4 -> 1962597.7 | V9: =V79*(Assumptions!$D$23-Assumptions!$D$22)/4 -> 2079000 | W9: =SUM(S9:V9) -> 7610367.2 | X9: =X79*(Assumptions!$D$23-Assumptions!$D$22)/4 -> 2193597.7 | Y9: =Y79*(Assumptions!$D$23-Assumptions!$D$22)/4 -> 2306390.6 | Z9: =Z79*(Assumptions!$D$23-Assumptions!$D$22)/4 -> 2417378.9 | AA9: =AA79*(Assumptions!$D$23-Assumptions!$D$22)/4 -> 2526562.5 | AB9: =SUM(X9:AA9) -> 9443929.7 | AC9: =AC79*(Assumptions!$D$23-Assumptions!$D$22)/4 -> 2508515.6 | AD9: =AD79*(Assumptions!$D$23-Assumptions!$D$22)/4 -> 2490468.8 | AE9: =AE79*(Assumptions!$D$23-Assumptions!$D$22)/4 -> 2472421.9 | AF9: =AF79*(Assumptions!$D$23-Assumptions!$D$22)/4 -> 2454375 | AG9: =SUM(AC9:AF9) -> 9925781.3 | AH9: =AH79*(Assumptions!$D$23-Assumptions!$D$22)/4 -> 2436328.1 | AI9: =AI79*(Assumptions!$D$23-Assumptions!$D$22)/4 -> 2418281.3 | AJ9: =AJ79*(Assumptions!$D$23-Assumptions!$D$22)/4 -> 2400234.4 | AK9: =AK79*(Assumptions!$D$23-Assumptions!$D$22)/4 -> 2382187.5 | AL9: =SUM(AH9:AK9) -> 9637031.3
C10: Net interest income on checking account balances | D10: =D80*(Assumptions!$D$23-Assumptions!$D$25)/4 -> 430417.97 | E10: =E80*(Assumptions!$D$23-Assumptions!$D$25)/4 -> 855421.88 | F10: =F80*(Assumptions!$D$23-Assumptions!$D$25)/4 -> 1275011.7 | G10: =G80*(Assumptions!$D$23-Assumptions!$D$25)/4 -> 1689187.5 | H10: =SUM(D10:G10) -> 4250039.1 | I10: =I80*(Assumptions!$D$23-Assumptions!$D$25)/4 -> 2097949.2 | J10: =J80*(Assumptions!$D$23-Assumptions!$D$25)/4 -> 2501296.9 | K10: =K80*(Assumptions!$D$23-Assumptions!$D$25)/4 -> 2899230.5 | L10: =L80*(Assumptions!$D$23-Assumptions!$D$25)/4 -> 3291750 | M10: =SUM(I10:L10) -> 10790227 | N10: =N80*(Assumptions!$D$23-Assumptions!$D$25)/4 -> 3678855.5 | O10: =O80*(Assumptions!$D$23-Assumptions!$D$25)/4 -> 4060546.9 | P10: =P80*(Assumptions!$D$23-Assumptions!$D$25)/4 -> 4436824.2 | Q10: =Q80*(Assumptions!$D$23-Assumptions!$D$25)/4 -> 4807687.5 | R10: =SUM(N10:Q10) -> 16983914 | S10: =S80*(Assumptions!$D$23-Assumptions!$D$25)/4 -> 5173136.7 | T10: =T80*(Assumptions!$D$23-Assumptions!$D$25)/4 -> 5533171.9 | U10: =U80*(Assumptions!$D$23-Assumptions!$D$25)/4 -> 5887793 | V10: =V80*(Assumptions!$D$23-Assumptions!$D$25)/4 -> 6237000 | W10: =SUM(S10:V10) -> 22831102 | X10: =X80*(Assumptions!$D$23-Assumptions!$D$25)/4 -> 6580793 | Y10: =Y80*(Assumptions!$D$23-Assumptions!$D$25)/4 -> 6919171.9 | Z10: =Z80*(Assumptions!$D$23-Assumptions!$D$25)/4 -> 7252136.7 | AA10: =AA80*(Assumptions!$D$23-Assumptions!$D$25)/4 -> 7579687.5 | AB10: =SUM(X10:AA10) -> 28331789 | AC10: =AC80*(Assumptions!$D$23-Assumptions!$D$25)/4 -> 7525546.9 | AD10: =AD80*(Assumptions!$D$23-Assumptions!$D$25)/4 -> 7471406.2 | AE10: =AE80*(Assumptions!$D$23-Assumptions!$D$25)/4 -> 7417265.6 | AF10: =AF80*(Assumptions!$D$23-Assumptions!$D$25)/4 -> 7363125 | AG10: =SUM(AC10:AF10) -> 29777344 | AH10: =AH80*(Assumptions!$D$23-Assumptions!$D$25)/4 -> 7308984.4 | AI10: =AI80*(Assumptions!$D$23-Assumptions!$D$25)/4 -> 7254843.8 | AJ10: =AJ80*(Assumptions!$D$23-Assumptions!$D$25)/4 -> 7200703.1 | AK10: =AK80*(Assumptions!$D$23-Assumptions!$D$25)/4 -> 7146562.5 | AL10: =SUM(AH10:AK10) -> 28911094
B11: Net interest income | D11: =SUM(D6:D10) -> 15916148 | E11: =SUM(E6:E10) -> 31632094 | F11: =SUM(F6:F10) -> 47147836 | G11: =SUM(G6:G10) -> 62463375 | H11: =SUM(D11:G11) -> 1.5715945e+08 | I11: =SUM(I6:I10) -> 77578711 | J11: =SUM(J6:J10) -> 92493844 | K11: =SUM(K6:K10) -> 1.0720877e+08 | L11: =SUM(L6:L10) -> 121723500 | M11: =SUM(I11:L11) -> 3.9900483e+08 | N11: =SUM(N6:N10) -> 1.3603802e+08 | O11: =SUM(O6:O10) -> 1.5015234e+08 | P11: =SUM(P6:P10) -> 1.6406646e+08 | Q11: =SUM(Q6:Q10) -> 1.7778038e+08 | R11: =SUM(N11:Q11) -> 6.280372e+08 | S11: =SUM(S6:S10) -> 1.9129409e+08 | T11: =SUM(T6:T10) -> 2.0460759e+08 | U11: =SUM(U6:U10) -> 2.177209e+08 | V11: =SUM(V6:V10) -> 230634000 | W11: =SUM(S11:V11) -> 8.4425658e+08 | X11: =SUM(X6:X10) -> 2.433469e+08 | Y11: =SUM(Y6:Y10) -> 2.5585959e+08 | Z11: =SUM(Z6:Z10) -> 2.6817209e+08 | AA11: =SUM(AA6:AA10) -> 280284375 | AB11: =SUM(X11:AA11) -> 1.047663e+09 | AC11: =SUM(AC6:AC10) -> 2.7828234e+08 | AD11: =SUM(AD6:AD10) -> 2.7628031e+08 | AE11: =SUM(AE6:AE10) -> 2.7427828e+08 | AF11: =SUM(AF6:AF10) -> 272276250 | AG11: =SUM(AC11:AF11) -> 1.1011172e+09 | AH11: =SUM(AH6:AH10) -> 2.7027422e+08 | AI11: =SUM(AI6:AI10) -> 2.6827219e+08 | AJ11: =SUM(AJ6:AJ10) -> 2.6627016e+08 | AK11: =SUM(AK6:AK10) -> 264268125 | AL11: =SUM(AH11:AK11) -> 1.0690847e+09
A12: NET INTEREST INCOME | D12: =D11 -> 15916148 | E12: =E11 -> 31632094 | F12: =F11 -> 47147836 | G12: =G11 -> 62463375 | H12: =SUM(D12:G12) -> 1.5715945e+08 | I12: =I11 -> 77578711 | J12: =J11 -> 92493844 | K12: =K11 -> 1.0720877e+08 | L12: =L11 -> 121723500 | M12: =SUM(I12:L12) -> 3.9900483e+08 | N12: =N11 -> 1.3603802e+08 | O12: =O11 -> 1.5015234e+08 | P12: =P11 -> 1.6406646e+08 | Q12: =Q11 -> 1.7778038e+08 | R12: =SUM(N12:Q12) -> 6.280372e+08 | S12: =S11 -> 1.9129409e+08 | T12: =T11 -> 2.0460759e+08 | U12: =U11 -> 2.177209e+08 | V12: =V11 -> 230634000 | W12: =SUM(S12:V12) -> 8.4425658e+08 | X12: =X11 -> 2.433469e+08 | Y12: =Y11 -> 2.5585959e+08 | Z12: =Z11 -> 2.6817209e+08 | AA12: =AA11 -> 280284375 | AB12: =SUM(X12:AA12) -> 1.047663e+09 | AC12: =AC11 -> 2.7828234e+08 | AD12: =AD11 -> 2.7628031e+08 | AE12: =AE11 -> 2.7427828e+08 | AF12: =AF11 -> 272276250 | AG12: =SUM(AC12:AF12) -> 1.1011172e+09 | AH12: =AH11 -> 2.7027422e+08 | AI12: =AI11 -> 2.6827219e+08 | AJ12: =AJ11 -> 2.6627016e+08 | AK12: =AK11 -> 264268125 | AL12: =SUM(AH12:AK12) -> 1.0690847e+09
C13: Net intrabank transaction fees income | D13: =(D81*(1-Assumptions!$D$17)*Assumptions!$D$26+D81*(Assumptions!$D$17)*Assumptions!$D$27) -> 1033003.1 | E13: =(E81*(1-Assumptions!$D$17)*Assumptions!$D$26+E81*(Assumptions!$D$17)*Assumptions!$D$27) -> 2053012.5 | F13: =(F81*(1-Assumptions!$D$17)*Assumptions!$D$26+F81*(Assumptions!$D$17)*Assumptions!$D$27) -> 3060028.1 | G13: =(G81*(1-Assumptions!$D$17)*Assumptions!$D$26+G81*(Assumptions!$D$17)*Assumptions!$D$27) -> 4054050 | H13: =SUM(D13:G13) -> 10200094 | I13: =(I81*(1-Assumptions!$D$17)*Assumptions!$D$26+I81*(Assumptions!$D$17)*Assumptions!$D$27) -> 5035078.1 | J13: =(J81*(1-Assumptions!$D$17)*Assumptions!$D$26+J81*(Assumptions!$D$17)*Assumptions!$D$27) -> 6003112.5 | K13: =(K81*(1-Assumptions!$D$17)*Assumptions!$D$26+K81*(Assumptions!$D$17)*Assumptions!$D$27) -> 6958153.1 | L13: =(L81*(1-Assumptions!$D$17)*Assumptions!$D$26+L81*(Assumptions!$D$17)*Assumptions!$D$27) -> 7900200 | M13: =SUM(I13:L13) -> 25896544 | N13: =(N81*(1-Assumptions!$D$17)*Assumptions!$D$26+N81*(Assumptions!$D$17)*Assumptions!$D$27) -> 8829253.1 | O13: =(O81*(1-Assumptions!$D$17)*Assumptions!$D$26+O81*(Assumptions!$D$17)*Assumptions!$D$27) -> 9745312.5 | P13: =(P81*(1-Assumptions!$D$17)*Assumptions!$D$26+P81*(Assumptions!$D$17)*Assumptions!$D$27) -> 10648378 | Q13: =(Q81*(1-Assumptions!$D$17)*Assumptions!$D$26+Q81*(Assumptions!$D$17)*Assumptions!$D$27) -> 11538450 | R13: =SUM(N13:Q13) -> 40761394 | S13: =(S81*(1-Assumptions!$D$17)*Assumptions!$D$26+S81*(Assumptions!$D$17)*Assumptions!$D$27) -> 12415528 | T13: =(T81*(1-Assumptions!$D$17)*Assumptions!$D$26+T81*(Assumptions!$D$17)*Assumptions!$D$27) -> 13279612 | U13: =(U81*(1-Assumptions!$D$17)*Assumptions!$D$26+U81*(Assumptions!$D$17)*Assumptions!$D$27) -> 14130703 | V13: =(V81*(1-Assumptions!$D$17)*Assumptions!$D$26+V81*(Assumptions!$D$17)*Assumptions!$D$27) -> 14968800 | W13: =SUM(S13:V13) -> 54794644 | X13: =(X81*(1-Assumptions!$D$17)*Assumptions!$D$26+X81*(Assumptions!$D$17)*Assumptions!$D$27) -> 15793903 | Y13: =(Y81*(1-Assumptions!$D$17)*Assumptions!$D$26+Y81*(Assumptions!$D$17)*Assumptions!$D$27) -> 16606012 | Z13: =(Z81*(1-Assumptions!$D$17)*Assumptions!$D$26+Z81*(Assumptions!$D$17)*Assumptions!$D$27) -> 17405128 | AA13: =(AA81*(1-Assumptions!$D$17)*Assumptions!$D$26+AA81*(Assumptions!$D$17)*Assumptions!$D$27) -> 18191250 | AB13: =SUM(X13:AA13) -> 67996294 | AC13: =(AC81*(1-Assumptions!$D$17)*Assumptions!$D$26+AC81*(Assumptions!$D$17)*Assumptions!$D$27) -> 18061312 | AD13: =(AD81*(1-Assumptions!$D$17)*Assumptions!$D$26+AD81*(Assumptions!$D$17)*Assumptions!$D$27) -> 17931375 | AE13: =(AE81*(1-Assumptions!$D$17)*Assumptions!$D$26+AE81*(Assumptions!$D$17)*Assumptions!$D$27) -> 17801438 | AF13: =(AF81*(1-Assumptions!$D$17)*Assumptions!$D$26+AF81*(Assumptions!$D$17)*Assumptions!$D$27) -> 17671500 | AG13: =SUM(AC13:AF13) -> 71465625 | AH13: =(AH81*(1-Assumptions!$D$17)*Assumptions!$D$26+AH81*(Assumptions!$D$17)*Assumptions!$D$27) -> 17541562 | AI13: =(AI81*(1-Assumptions!$D$17)*Assumptions!$D$26+AI81*(Assumptions!$D$17)*Assumptions!$D$27) -> 17411625 | AJ13: =(AJ81*(1-Assumptions!$D$17)*Assumptions!$D$26+AJ81*(Assumptions!$D$17)*Assumptions!$D$27) -> 17281688 | AK13: =(AK81*(1-Assumptions!$D$17)*Assumptions!$D$26+AK81*(Assumptions!$D$17)*Assumptions!$D$27) -> 17151750 | AL13: =SUM(AH13:AK13) -> 69386625
C14: Net interbank transaction fees income | D14: =(D82*(1-Assumptions!$D$17)*Assumptions!$D$28+D82*(Assumptions!$D$17)*Assumptions!$D$29) -> 2582507.8 | E14: =(E82*(1-Assumptions!$D$17)*Assumptions!$D$28+E82*(Assumptions!$D$17)*Assumptions!$D$29) -> 5132531.2 | F14: =(F82*(1-Assumptions!$D$17)*Assumptions!$D$28+F82*(Assumptions!$D$17)*Assumptions!$D$29) -> 7650070.3 | G14: =(G82*(1-Assumptions!$D$17)*Assumptions!$D$28+G82*(Assumptions!$D$17)*Assumptions!$D$29) -> 10135125 | H14: =SUM(D14:G14) -> 25500234 | I14: =(I82*(1-Assumptions!$D$17)*Assumptions!$D$28+I82*(Assumptions!$D$17)*Assumptions!$D$29) -> 12587695 | J14: =(J82*(1-Assumptions!$D$17)*Assumptions!$D$28+J82*(Assumptions!$D$17)*Assumptions!$D$29) -> 15007781 | K14: =(K82*(1-Assumptions!$D$17)*Assumptions!$D$28+K82*(Assumptions!$D$17)*Assumptions!$D$29) -> 17395383 | L14: =(L82*(1-Assumptions!$D$17)*Assumptions!$D$28+L82*(Assumptions!$D$17)*Assumptions!$D$29) -> 19750500 | M14: =SUM(I14:L14) -> 64741359 | N14: =(N82*(1-Assumptions!$D$17)*Assumptions!$D$28+N82*(Assumptions!$D$17)*Assumptions!$D$29) -> 22073133 | O14: =(O82*(1-Assumptions!$D$17)*Assumptions!$D$28+O82*(Assumptions!$D$17)*Assumptions!$D$29) -> 24363281 | P14: =(P82*(1-Assumptions!$D$17)*Assumptions!$D$28+P82*(Assumptions!$D$17)*Assumptions!$D$29) -> 26620945 | Q14: =(Q82*(1-Assumptions!$D$17)*Assumptions!$D$28+Q82*(Assumptions!$D$17)*Assumptions!$D$29) -> 28846125 | R14: =SUM(N14:Q14) -> 1.0190348e+08 | S14: =(S82*(1-Assumptions!$D$17)*Assumptions!$D$28+S82*(Assumptions!$D$17)*Assumptions!$D$29) -> 31038820 | T14: =(T82*(1-Assumptions!$D$17)*Assumptions!$D$28+T82*(Assumptions!$D$17)*Assumptions!$D$29) -> 33199031 | U14: =(U82*(1-Assumptions!$D$17)*Assumptions!$D$28+U82*(Assumptions!$D$17)*Assumptions!$D$29) -> 35326758 | V14: =(V82*(1-Assumptions!$D$17)*Assumptions!$D$28+V82*(Assumptions!$D$17)*Assumptions!$D$29) -> 37422000 | W14: =SUM(S14:V14) -> 1.3698661e+08 | X14: =(X82*(1-Assumptions!$D$17)*Assumptions!$D$28+X82*(Assumptions!$D$17)*Assumptions!$D$29) -> 39484758 | Y14: =(Y82*(1-Assumptions!$D$17)*Assumptions!$D$28+Y82*(Assumptions!$D$17)*Assumptions!$D$29) -> 41515031 | Z14: =(Z82*(1-Assumptions!$D$17)*Assumptions!$D$28+Z82*(Assumptions!$D$17)*Assumptions!$D$29) -> 43512820 | AA14: =(AA82*(1-Assumptions!$D$17)*Assumptions!$D$28+AA82*(Assumptions!$D$17)*Assumptions!$D$29) -> 45478125 | AB14: =SUM(X14:AA14) -> 1.6999073e+08 | AC14: =(AC82*(1-Assumptions!$D$17)*Assumptions!$D$28+AC82*(Assumptions!$D$17)*Assumptions!$D$29) -> 45153281 | AD14: =(AD82*(1-Assumptions!$D$17)*Assumptions!$D$28+AD82*(Assumptions!$D$17)*Assumptions!$D$29) -> 44828438 | AE14: =(AE82*(1-Assumptions!$D$17)*Assumptions!$D$28+AE82*(Assumptions!$D$17)*Assumptions!$D$29) -> 44503594 | AF14: =(AF82*(1-Assumptions!$D$17)*Assumptions!$D$28+AF82*(Assumptions!$D$17)*Assumptions!$D$29) -> 44178750 | AG14: =SUM(AC14:AF14) -> 1.7866406e+08 | AH14: =(AH82*(1-Assumptions!$D$17)*Assumptions!$D$28+AH82*(Assumptions!$D$17)*Assumptions!$D$29) -> 43853906 | AI14: =(AI82*(1-Assumptions!$D$17)*Assumptions!$D$28+AI82*(Assumptions!$D$17)*Assumptions!$D$29) -> 43529062 | AJ14: =(AJ82*(1-Assumptions!$D$17)*Assumptions!$D$28+AJ82*(Assumptions!$D$17)*Assumptions!$D$29) -> 43204219 | AK14: =(AK82*(1-Assumptions!$D$17)*Assumptions!$D$28+AK82*(Assumptions!$D$17)*Assumptions!$D$29) -> 42879375 | AL14: =SUM(AH14:AK14) -> 1.7346656e+08
C15: Net international transaction fees income | D15: =(D82*(1-Assumptions!$D$17)*Assumptions!$D$30+D82*(Assumptions!$D$17)*Assumptions!$D$31) -> 5165015.6 | E15: =(E82*(1-Assumptions!$D$17)*Assumptions!$D$30+E82*(Assumptions!$D$17)*Assumptions!$D$31) -> 10265062 | F15: =(F82*(1-Assumptions!$D$17)*Assumptions!$D$30+F82*(Assumptions!$D$17)*Assumptions!$D$31) -> 15300141 | G15: =(G82*(1-Assumptions!$D$17)*Assumptions!$D$30+G82*(Assumptions!$D$17)*Assumptions!$D$31) -> 20270250 | H15: =SUM(D15:G15) -> 51000469 | I15: =(I82*(1-Assumptions!$D$17)*Assumptions!$D$30+I82*(Assumptions!$D$17)*Assumptions!$D$31) -> 25175391 | J15: =(J82*(1-Assumptions!$D$17)*Assumptions!$D$30+J82*(Assumptions!$D$17)*Assumptions!$D$31) -> 30015562 | K15: =(K82*(1-Assumptions!$D$17)*Assumptions!$D$30+K82*(Assumptions!$D$17)*Assumptions!$D$31) -> 34790766 | L15: =(L82*(1-Assumptions!$D$17)*Assumptions!$D$30+L82*(Assumptions!$D$17)*Assumptions!$D$31) -> 39501000 | M15: =SUM(I15:L15) -> 1.2948272e+08 | N15: =(N82*(1-Assumptions!$D$17)*Assumptions!$D$30+N82*(Assumptions!$D$17)*Assumptions!$D$31) -> 44146266 | O15: =(O82*(1-Assumptions!$D$17)*Assumptions!$D$30+O82*(Assumptions!$D$17)*Assumptions!$D$31) -> 48726562 | P15: =(P82*(1-Assumptions!$D$17)*Assumptions!$D$30+P82*(Assumptions!$D$17)*Assumptions!$D$31) -> 53241891 | Q15: =(Q82*(1-Assumptions!$D$17)*Assumptions!$D$30+Q82*(Assumptions!$D$17)*Assumptions!$D$31) -> 57692250 | R15: =SUM(N15:Q15) -> 2.0380697e+08 | S15: =(S82*(1-Assumptions!$D$17)*Assumptions!$D$30+S82*(Assumptions!$D$17)*Assumptions!$D$31) -> 62077641 | T15: =(T82*(1-Assumptions!$D$17)*Assumptions!$D$30+T82*(Assumptions!$D$17)*Assumptions!$D$31) -> 66398062 | U15: =(U82*(1-Assumptions!$D$17)*Assumptions!$D$30+U82*(Assumptions!$D$17)*Assumptions!$D$31) -> 70653516 | V15: =(V82*(1-Assumptions!$D$17)*Assumptions!$D$30+V82*(Assumptions!$D$17)*Assumptions!$D$31) -> 74844000 | W15: =SUM(S15:V15) -> 2.7397322e+08 | X15: =(X82*(1-Assumptions!$D$17)*Assumptions!$D$30+X82*(Assumptions!$D$17)*Assumptions!$D$31) -> 78969516 | Y15: =(Y82*(1-Assumptions!$D$17)*Assumptions!$D$30+Y82*(Assumptions!$D$17)*Assumptions!$D$31) -> 83030062 | Z15: =(Z82*(1-Assumptions!$D$17)*Assumptions!$D$30+Z82*(Assumptions!$D$17)*Assumptions!$D$31) -> 87025641 | AA15: =(AA82*(1-Assumptions!$D$17)*Assumptions!$D$30+AA82*(Assumptions!$D$17)*Assumptions!$D$31) -> 90956250 | AB15: =SUM(X15:AA15) -> 3.3998147e+08 | AC15: =(AC82*(1-Assumptions!$D$17)*Assumptions!$D$30+AC82*(Assumptions!$D$17)*Assumptions!$D$31) -> 90306562 | AD15: =(AD82*(1-Assumptions!$D$17)*Assumptions!$D$30+AD82*(Assumptions!$D$17)*Assumptions!$D$31) -> 89656875 | AE15: =(AE82*(1-Assumptions!$D$17)*Assumptions!$D$30+AE82*(Assumptions!$D$17)*Assumptions!$D$31) -> 89007188 | AF15: =(AF82*(1-Assumptions!$D$17)*Assumptions!$D$30+AF82*(Assumptions!$D$17)*Assumptions!$D$31) -> 88357500 | AG15: =SUM(AC15:AF15) -> 357328125 | AH15: =(AH82*(1-Assumptions!$D$17)*Assumptions!$D$30+AH82*(Assumptions!$D$17)*Assumptions!$D$31) -> 87707812 | AI15: =(AI82*(1-Assumptions!$D$17)*Assumptions!$D$30+AI82*(Assumptions!$D$17)*Assumptions!$D$31) -> 87058125 | AJ15: =(AJ82*(1-Assumptions!$D$17)*Assumptions!$D$30+AJ82*(Assumptions!$D$17)*Assumptions!$D$31) -> 86408438 | AK15: =(AK82*(1-Assumptions!$D$17)*Assumptions!$D$30+AK82*(Assumptions!$D$17)*Assumptions!$D$31) -> 85758750 | AL15: =SUM(AH15:AK15) -> 346933125
C16: Loan processing fees income | D16: =(D76+D77+D78)*Assumptions!$D$32 -> 25047469 | E16: =(E76+E77+E78-D76-D77-D78)*Assumptions!$D$34 -> 24732406 | F16: =(F76+F77+F78-E76-E77-E78)*Assumptions!$D$34 -> 24417344 | G16: =(G76+G77+G78-F76-F77-F78)*Assumptions!$D$34 -> 24102281 | H16: =SUM(D16:G16) -> 98299500 | I16: =(I76+I77+I78-H76-H77-H78)*Assumptions!$D$34 -> 23787219 | J16: =(J76+J77+J78-I76-I77-I78)*Assumptions!$D$34 -> 23472156 | K16: =(K76+K77+K78-J76-J77-J78)*Assumptions!$D$34 -> 23157094 | L16: =(L76+L77+L78-K76-K77-K78)*Assumptions!$D$34 -> 22842031 | M16: =SUM(I16:L16) -> 93258500 | N16: =(N76+N77+N78-M76-M77-M78)*Assumptions!$D$34 -> 22526969 | O16: =(O76+O77+O78-N76-N77-N78)*Assumptions!$D$34 -> 22211906 | P16: =(P76+P77+P78-O76-O77-O78)*Assumptions!$D$34 -> 21896844 | Q16: =(Q76+Q77+Q78-P76-P77-P78)*Assumptions!$D$34 -> 21581781 | R16: =SUM(N16:Q16) -> 88217500 | S16: =(S76+S77+S78-R76-R77-R78)*Assumptions!$D$34 -> 21266719 | T16: =(T76+T77+T78-S76-S77-S78)*Assumptions!$D$34 -> 20951656 | U16: =(U76+U77+U78-T76-T77-T78)*Assumptions!$D$34 -> 20636594 | V16: =(V76+V77+V78-U76-U77-U78)*Assumptions!$D$34 -> 20321531 | W16: =SUM(S16:V16) -> 83176500 | X16: =(X76+X77+X78-W76-W77-W78)*Assumptions!$D$34 -> 20006469 | Y16: =(Y76+Y77+Y78-X76-X77-X78)*Assumptions!$D$34 -> 19691406 | Z16: =(Z76+Z77+Z78-Y76-Y77-Y78)*Assumptions!$D$34 -> 19376344 | AA16: =(AA76+AA77+AA78-Z76-Z77-Z78)*Assumptions!$D$34 -> 19061281 | AB16: =SUM(X16:AA16) -> 78135500 | AC16: =(AC76+AC77+AC78-AB76-AB77-AB78)*Assumptions!$D$34 -> -3150625 | AD16: =(AD76+AD77+AD78-AC76-AC77-AC78)*Assumptions!$D$34 -> -3150625 | AE16: =(AE76+AE77+AE78-AD76-AD77-AD78)*Assumptions!$D$34 -> -3150625 | AF16: =(AF76+AF77+AF78-AE76-AE77-AE78)*Assumptions!$D$34 -> -3150625 | AG16: =SUM(AC16:AF16) -> -12602500 | AH16: =(AH76+AH77+AH78-AG76-AG77-AG78)*Assumptions!$D$34 -> -3150625 | AI16: =(AI76+AI77+AI78-AH76-AH77-AH78)*Assumptions!$D$34 -> -3150625 | AJ16: =(AJ76+AJ77+AJ78-AI76-AI77-AI78)*Assumptions!$D$34 -> -3150625 | AK16: =(AK76+AK77+AK78-AJ76-AJ77-AJ78)*Assumptions!$D$34 -> -3150625 | AL16: =SUM(AH16:AK16) -> -12602500
B17: Fee income | D17: =SUM(D13:D16) -> 33827995 | E17: =SUM(E13:E16) -> 42183012 | F17: =SUM(F13:F16) -> 50427583 | G17: =SUM(G13:G16) -> 58561706 | H17: =SUM(D17:G17) -> 1.850003e+08 | I17: =SUM(I13:I16) -> 66585383 | J17: =SUM(J13:J16) -> 74498612 | K17: =SUM(K13:K16) -> 82301395 | L17: =SUM(L13:L16) -> 89993731 | M17: =SUM(I17:L17) -> 3.1337912e+08 | N17: =SUM(N13:N16) -> 97575620 | O17: =SUM(O13:O16) -> 1.0504706e+08 | P17: =SUM(P13:P16) -> 1.1240806e+08 | Q17: =SUM(Q13:Q16) -> 1.1965861e+08 | R17: =SUM(N17:Q17) -> 4.3468935e+08 | S17: =SUM(S13:S16) -> 1.2679871e+08 | T17: =SUM(T13:T16) -> 1.3382836e+08 | U17: =SUM(U13:U16) -> 1.4074757e+08 | V17: =SUM(V13:V16) -> 1.4755633e+08 | W17: =SUM(S17:V17) -> 5.4893097e+08 | X17: =SUM(X13:X16) -> 1.5425465e+08 | Y17: =SUM(Y13:Y16) -> 1.6084251e+08 | Z17: =SUM(Z13:Z16) -> 1.6731993e+08 | AA17: =SUM(AA13:AA16) -> 1.7368691e+08 | AB17: =SUM(X17:AA17) -> 6.56104e+08 | AC17: =SUM(AC13:AC16) -> 1.5037053e+08 | AD17: =SUM(AD13:AD16) -> 1.4926606e+08 | AE17: =SUM(AE13:AE16) -> 1.4816159e+08 | AF17: =SUM(AF13:AF16) -> 147057125 | AG17: =SUM(AC17:AF17) -> 5.9485531e+08 | AH17: =SUM(AH13:AH16) -> 1.4595266e+08 | AI17: =SUM(AI13:AI16) -> 1.4484819e+08 | AJ17: =SUM(AJ13:AJ16) -> 1.4374372e+08 | AK17: =SUM(AK13:AK16) -> 142639250 | AL17: =SUM(AH17:AK17) -> 5.7718381e+08
A18: NET FEE INCOME | D18: =D17 -> 33827995 | E18: =E17 -> 42183012 | F18: =F17 -> 50427583 | G18: =G17 -> 58561706 | H18: =SUM(D18:G18) -> 1.850003e+08 | I18: =I17 -> 66585383 | J18: =J17 -> 74498612 | K18: =K17 -> 82301395 | L18: =L17 -> 89993731 | M18: =SUM(I18:L18) -> 3.1337912e+08 | N18: =N17 -> 97575620 | O18: =O17 -> 1.0504706e+08 | P18: =P17 -> 1.1240806e+08 | Q18: =Q17 -> 1.1965861e+08 | R18: =SUM(N18:Q18) -> 4.3468935e+08 | S18: =S17 -> 1.2679871e+08 | T18: =T17 -> 1.3382836e+08 | U18: =U17 -> 1.4074757e+08 | V18: =V17 -> 1.4755633e+08 | W18: =SUM(S18:V18) -> 5.4893097e+08 | X18: =X17 -> 1.5425465e+08 | Y18: =Y17 -> 1.6084251e+08 | Z18: =Z17 -> 1.6731993e+08 | AA18: =AA17 -> 1.7368691e+08 | AB18: =SUM(X18:AA18) -> 6.56104e+08 | AC18: =AC17 -> 1.5037053e+08 | AD18: =AD17 -> 1.4926606e+08 | AE18: =AE17 -> 1.4816159e+08 | AF18: =AF17 -> 147057125 | AG18: =SUM(AC18:AF18) -> 5.9485531e+08 | AH18: =AH17 -> 1.4595266e+08 | AI18: =AI17 -> 1.4484819e+08 | AJ18: =AJ17 -> 1.4374372e+08 | AK18: =AK17 -> 142639250 | AL18: =SUM(AH18:AK18) -> 5.7718381e+08
C19: Insurance premium income | D19: =SUM(D72:D75)*Assumptions!$D$55*Assumptions!$D$56/4/VLOOKUP(Assumptions!$D$7, Lists!$B$7:$C$10, 2, FALSE) -> 5738906.2 | E19: =SUM(E72:E75)*Assumptions!$D$55*Assumptions!$D$56/4/VLOOKUP(Assumptions!$D$7, Lists!$B$7:$C$10, 2, FALSE) -> 11405625 | F19: =SUM(F72:F75)*Assumptions!$D$55*Assumptions!$D$56/4/VLOOKUP(Assumptions!$D$7, Lists!$B$7:$C$10, 2, FALSE) -> 17000156 | G19: =SUM(G72:G75)*Assumptions!$D$55*Assumptions!$D$56/4/VLOOKUP(Assumptions!$D$7, Lists!$B$7:$C$10, 2, FALSE) -> 22522500 | H19: =SUM(D19:G19) -> 56667188 | I19: =SUM(I72:I75)*Assumptions!$D$55*Assumptions!$D$56/4/VLOOKUP(Assumptions!$D$7, Lists!$B$7:$C$10, 2, FALSE) -> 27972656 | J19: =SUM(J72:J75)*Assumptions!$D$55*Assumptions!$D$56/4/VLOOKUP(Assumptions!$D$7, Lists!$B$7:$C$10, 2, FALSE) -> 33350625 | K19: =SUM(K72:K75)*Assumptions!$D$55*Assumptions!$D$56/4/VLOOKUP(Assumptions!$D$7, Lists!$B$7:$C$10, 2, FALSE) -> 38656406 | L19: =SUM(L72:L75)*Assumptions!$D$55*Assumptions!$D$56/4/VLOOKUP(Assumptions!$D$7, Lists!$B$7:$C$10, 2, FALSE) -> 43890000 | M19: =SUM(I19:L19) -> 1.4386969e+08 | N19: =SUM(N72:N75)*Assumptions!$D$55*Assumptions!$D$56/4/VLOOKUP(Assumptions!$D$7, Lists!$B$7:$C$10, 2, FALSE) -> 49051406 | O19: =SUM(O72:O75)*Assumptions!$D$55*Assumptions!$D$56/4/VLOOKUP(Assumptions!$D$7, Lists!$B$7:$C$10, 2, FALSE) -> 54140625 | P19: =SUM(P72:P75)*Assumptions!$D$55*Assumptions!$D$56/4/VLOOKUP(Assumptions!$D$7, Lists!$B$7:$C$10, 2, FALSE) -> 59157656 | Q19: =SUM(Q72:Q75)*Assumptions!$D$55*Assumptions!$D$56/4/VLOOKUP(Assumptions!$D$7, Lists!$B$7:$C$10, 2, FALSE) -> 64102500 | R19: =SUM(N19:Q19) -> 2.2645219e+08 | S19: =SUM(S72:S75)*Assumptions!$D$55*Assumptions!$D$56/4/VLOOKUP(Assumptions!$D$7, Lists!$B$7:$C$10, 2, FALSE) -> 68975156 | T19: =SUM(T72:T75)*Assumptions!$D$55*Assumptions!$D$56/4/VLOOKUP(Assumptions!$D$7, Lists!$B$7:$C$10, 2, FALSE) -> 73775625 | U19: =SUM(U72:U75)*Assumptions!$D$55*Assumptions!$D$56/4/VLOOKUP(Assumptions!$D$7, Lists!$B$7:$C$10, 2, FALSE) -> 78503906 | V19: =SUM(V72:V75)*Assumptions!$D$55*Assumptions!$D$56/4/VLOOKUP(Assumptions!$D$7, Lists!$B$7:$C$10, 2, FALSE) -> 83160000 | W19: =SUM(S19:V19) -> 3.0441469e+08 | X19: =SUM(X72:X75)*Assumptions!$D$55*Assumptions!$D$56/4/VLOOKUP(Assumptions!$D$7, Lists!$B$7:$C$10, 2, FALSE) -> 87743906 | Y19: =SUM(Y72:Y75)*Assumptions!$D$55*Assumptions!$D$56/4/VLOOKUP(Assumptions!$D$7, Lists!$B$7:$C$10, 2, FALSE) -> 92255625 | Z19: =SUM(Z72:Z75)*Assumptions!$D$55*Assumptions!$D$56/4/VLOOKUP(Assumptions!$D$7, Lists!$B$7:$C$10, 2, FALSE) -> 96695156 | AA19: =SUM(AA72:AA75)*Assumptions!$D$55*Assumptions!$D$56/4/VLOOKUP(Assumptions!$D$7, Lists!$B$7:$C$10, 2, FALSE) -> 101062500 | AB19: =SUM(X19:AA19) -> 3.7775719e+08 | AC19: =SUM(AC72:AC75)*Assumptions!$D$55*Assumptions!$D$56/4/VLOOKUP(Assumptions!$D$7, Lists!$B$7:$C$10, 2, FALSE) -> 100340625 | AD19: =SUM(AD72:AD75)*Assumptions!$D$55*Assumptions!$D$56/4/VLOOKUP(Assumptions!$D$7, Lists!$B$7:$C$10, 2, FALSE) -> 99618750 | AE19: =SUM(AE72:AE75)*Assumptions!$D$55*Assumptions!$D$56/4/VLOOKUP(Assumptions!$D$7, Lists!$B$7:$C$10, 2, FALSE) -> 98896875 | AF19: =SUM(AF72:AF75)*Assumptions!$D$55*Assumptions!$D$56/4/VLOOKUP(Assumptions!$D$7, Lists!$B$7:$C$10, 2, FALSE) -> 98175000 | AG19: =SUM(AC19:AF19) -> 397031250 | AH19: =SUM(AH72:AH75)*Assumptions!$D$55*Assumptions!$D$56/4/VLOOKUP(Assumptions!$D$7, Lists!$B$7:$C$10, 2, FALSE) -> 97453125 | AI19: =SUM(AI72:AI75)*Assumptions!$D$55*Assumptions!$D$56/4/VLOOKUP(Assumptions!$D$7, Lists!$B$7:$C$10, 2, FALSE) -> 96731250 | AJ19: =SUM(AJ72:AJ75)*Assumptions!$D$55*Assumptions!$D$56/4/VLOOKUP(Assumptions!$D$7, Lists!$B$7:$C$10, 2, FALSE) -> 96009375 | AK19: =SUM(AK72:AK75)*Assumptions!$D$55*Assumptions!$D$56/4/VLOOKUP(Assumptions!$D$7, Lists!$B$7:$C$10, 2, FALSE) -> 95287500 | AL19: =SUM(AH19:AK19) -> 385481250
C20: Non-financial services (NFS) income | D20: =Assumptions!$D$57/4/VLOOKUP(Assumptions!$D$7, Lists!$B$7:$C$10, 2, FALSE) -> 2500000 | E20: =Assumptions!$D$57/4/VLOOKUP(Assumptions!$D$7, Lists!$B$7:$C$10, 2, FALSE) -> 2500000 | F20: =Assumptions!$D$57/4/VLOOKUP(Assumptions!$D$7, Lists!$B$7:$C$10, 2, FALSE) -> 2500000 | G20: =Assumptions!$D$57/4/VLOOKUP(Assumptions!$D$7, Lists!$B$7:$C$10, 2, FALSE) -> 2500000 | H20: =SUM(D20:G20) -> 10000000 | I20: =Assumptions!$D$57/4/VLOOKUP(Assumptions!$D$7, Lists!$B$7:$C$10, 2, FALSE) -> 2500000 | J20: =Assumptions!$D$57/4/VLOOKUP(Assumptions!$D$7, Lists!$B$7:$C$10, 2, FALSE) -> 2500000 | K20: =Assumptions!$D$57/4/VLOOKUP(Assumptions!$D$7, Lists!$B$7:$C$10, 2, FALSE) -> 2500000 | L20: =Assumptions!$D$57/4/VLOOKUP(Assumptions!$D$7, Lists!$B$7:$C$10, 2, FALSE) -> 2500000 | M20: =SUM(I20:L20) -> 10000000 | N20: =Assumptions!$D$57/4/VLOOKUP(Assumptions!$D$7, Lists!$B$7:$C$10, 2, FALSE) -> 2500000 | O20: =Assumptions!$D$57/4/VLOOKUP(Assumptions!$D$7, Lists!$B$7:$C$10, 2, FALSE) -> 2500000 | P20: =Assumptions!$D$57/4/VLOOKUP(Assumptions!$D$7, Lists!$B$7:$C$10, 2, FALSE) -> 2500000 | Q20: =Assumptions!$D$57/4/VLOOKUP(Assumptions!$D$7, Lists!$B$7:$C$10, 2, FALSE) -> 2500000 | R20: =SUM(N20:Q20) -> 10000000 | S20: =Assumptions!$D$57/4/VLOOKUP(Assumptions!$D$7, Lists!$B$7:$C$10, 2, FALSE) -> 2500000 | T20: =Assumptions!$D$57/4/VLOOKUP(Assumptions!$D$7, Lists!$B$7:$C$10, 2, FALSE) -> 2500000 | U20: =Assumptions!$D$57/4/VLOOKUP(Assumptions!$D$7, Lists!$B$7:$C$10, 2, FALSE) -> 2500000 | V20: =Assumptions!$D$57/4/VLOOKUP(Assumptions!$D$7, Lists!$B$7:$C$10, 2, FALSE) -> 2500000 | W20: =SUM(S20:V20) -> 10000000 | X20: =Assumptions!$D$57/4/VLOOKUP(Assumptions!$D$7, Lists!$B$7:$C$10, 2, FALSE) -> 2500000 | Y20: =Assumptions!$D$57/4/VLOOKUP(Assumptions!$D$7, Lists!$B$7:$C$10, 2, FALSE) -> 2500000 | Z20: =Assumptions!$D$57/4/VLOOKUP(Assumptions!$D$7, Lists!$B$7:$C$10, 2, FALSE) -> 2500000 | AA20: =Assumptions!$D$57/4/VLOOKUP(Assumptions!$D$7, Lists!$B$7:$C$10, 2, FALSE) -> 2500000 | AB20: =SUM(X20:AA20) -> 10000000 | AC20: =Assumptions!$D$57/4/VLOOKUP(Assumptions!$D$7, Lists!$B$7:$C$10, 2, FALSE) -> 2500000 | AD20: =Assumptions!$D$57/4/VLOOKUP(Assumptions!$D$7, Lists!$B$7:$C$10, 2, FALSE) -> 2500000 | AE20: =Assumptions!$D$57/4/VLOOKUP(Assumptions!$D$7, Lists!$B$7:$C$10, 2, FALSE) -> 2500000 | AF20: =Assumptions!$D$57/4/VLOOKUP(Assumptions!$D$7, Lists!$B$7:$C$10, 2, FALSE) -> 2500000 | AG20: =SUM(AC20:AF20) -> 10000000 | AH20: =Assumptions!$D$57/4/VLOOKUP(Assumptions!$D$7, Lists!$B$7:$C$10, 2, FALSE) -> 2500000 | AI20: =Assumptions!$D$57/4/VLOOKUP(Assumptions!$D$7, Lists!$B$7:$C$10, 2, FALSE) -> 2500000 | AJ20: =Assumptions!$D$57/4/VLOOKUP(Assumptions!$D$7, Lists!$B$7:$C$10, 2, FALSE) -> 2500000 | AK20: =Assumptions!$D$57/4/VLOOKUP(Assumptions!$D$7, Lists!$B$7:$C$10, 2, FALSE) -> 2500000 | AL20: =SUM(AH20:AK20) -> 10000000
C21: Non-financial services (NFS) costs | D21: =-Assumptions!$D$58/4/VLOOKUP(Assumptions!$D$7, Lists!$B$7:$C$10, 2, FALSE) -> -6250000 | E21: =-Assumptions!$D$58/4/VLOOKUP(Assumptions!$D$7, Lists!$B$7:$C$10, 2, FALSE) -> -6250000 | F21: =-Assumptions!$D$58/4/VLOOKUP(Assumptions!$D$7, Lists!$B$7:$C$10, 2, FALSE) -> -6250000 | G21: =-Assumptions!$D$58/4/VLOOKUP(Assumptions!$D$7, Lists!$B$7:$C$10, 2, FALSE) -> -6250000 | H21: =SUM(D21:G21) -> -25000000 | I21: =-Assumptions!$D$58/4/VLOOKUP(Assumptions!$D$7, Lists!$B$7:$C$10, 2, FALSE) -> -6250000 | J21: =-Assumptions!$D$58/4/VLOOKUP(Assumptions!$D$7, Lists!$B$7:$C$10, 2, FALSE) -> -6250000 | K21: =-Assumptions!$D$58/4/VLOOKUP(Assumptions!$D$7, Lists!$B$7:$C$10, 2, FALSE) -> -6250000 | L21: =-Assumptions!$D$58/4/VLOOKUP(Assumptions!$D$7, Lists!$B$7:$C$10, 2, FALSE) -> -6250000 | M21: =SUM(I21:L21) -> -25000000 | N21: =-Assumptions!$D$58/4/VLOOKUP(Assumptions!$D$7, Lists!$B$7:$C$10, 2, FALSE) -> -6250000 | O21: =-Assumptions!$D$58/4/VLOOKUP(Assumptions!$D$7, Lists!$B$7:$C$10, 2, FALSE) -> -6250000 | P21: =-Assumptions!$D$58/4/VLOOKUP(Assumptions!$D$7, Lists!$B$7:$C$10, 2, FALSE) -> -6250000 | Q21: =-Assumptions!$D$58/4/VLOOKUP(Assumptions!$D$7, Lists!$B$7:$C$10, 2, FALSE) -> -6250000 | R21: =SUM(N21:Q21) -> -25000000 | S21: =-Assumptions!$D$58/4/VLOOKUP(Assumptions!$D$7, Lists!$B$7:$C$10, 2, FALSE) -> -6250000 | T21: =-Assumptions!$D$58/4/VLOOKUP(Assumptions!$D$7, Lists!$B$7:$C$10, 2, FALSE) -> -6250000 | U21: =-Assumptions!$D$58/4/VLOOKUP(Assumptions!$D$7, Lists!$B$7:$C$10, 2, FALSE) -> -6250000 | V21: =-Assumptions!$D$58/4/VLOOKUP(Assumptions!$D$7, Lists!$B$7:$C$10, 2, FALSE) -> -6250000 | W21: =SUM(S21:V21) -> -25000000 | X21: =-Assumptions!$D$58/4/VLOOKUP(Assumptions!$D$7, Lists!$B$7:$C$10, 2, FALSE) -> -6250000 | Y21: =-Assumptions!$D$58/4/VLOOKUP(Assumptions!$D$7, Lists!$B$7:$C$10, 2, FALSE) -> -6250000 | Z21: =-Assumptions!$D$58/4/VLOOKUP(Assumptions!$D$7, Lists!$B$7:$C$10, 2, FALSE) -> -6250000 | AA21: =-Assumptions!$D$58/4/VLOOKUP(Assumptions!$D$7, Lists!$B$7:$C$10, 2, FALSE) -> -6250000 | AB21: =SUM(X21:AA21) -> -25000000 | AC21: =-Assumptions!$D$58/4/VLOOKUP(Assumptions!$D$7, Lists!$B$7:$C$10, 2, FALSE) -> -6250000 | AD21: =-Assumptions!$D$58/4/VLOOKUP(Assumptions!$D$7, Lists!$B$7:$C$10, 2, FALSE) -> -6250000 | AE21: =-Assumptions!$D$58/4/VLOOKUP(Assumptions!$D$7, Lists!$B$7:$C$10, 2, FALSE) -> -6250000 | AF21: =-Assumptions!$D$58/4/VLOOKUP(Assumptions!$D$7, Lists!$B$7:$C$10, 2, FALSE) -> -6250000 | AG21: =SUM(AC21:AF21) -> -25000000 | AH21: =-Assumptions!$D$58/4/VLOOKUP(Assumptions!$D$7, Lists!$B$7:$C$10, 2, FALSE) -> -6250000 | AI21: =-Assumptions!$D$58/4/VLOOKUP(Assumptions!$D$7, Lists!$B$7:$C$10, 2, FALSE) -> -6250000 | AJ21: =-Assumptions!$D$58/4/VLOOKUP(Assumptions!$D$7, Lists!$B$7:$C$10, 2, FALSE) -> -6250000 | AK21: =-Assumptions!$D$58/4/VLOOKUP(Assumptions!$D$7, Lists!$B$7:$C$10, 2, FALSE) -> -6250000 | AL21: =SUM(AH21:AK21) -> -25000000
C22: Net income from non-financial services | D22: =D20+D21 -> -3750000 | E22: =E20+E21 -> -3750000 | F22: =F20+F21 -> -3750000 | G22: =G20+G21 -> -3750000 | H22: =SUM(D22:G22) -> -15000000 | I22: =I20+I21 -> -3750000 | J22: =J20+J21 -> -3750000 | K22: =K20+K21 -> -3750000 | L22: =L20+L21 -> -3750000 | M22: =SUM(I22:L22) -> -15000000 | N22: =N20+N21 -> -3750000 | O22: =O20+O21 -> -3750000 | P22: =P20+P21 -> -3750000 | Q22: =Q20+Q21 -> -3750000 | R22: =SUM(N22:Q22) -> -15000000 | S22: =S20+S21 -> -3750000 | T22: =T20+T21 -> -3750000 | U22: =U20+U21 -> -3750000 | V22: =V20+V21 -> -3750000 | W22: =SUM(S22:V22) -> -15000000 | X22: =X20+X21 -> -3750000 | Y22: =Y20+Y21 -> -3750000 | Z22: =Z20+Z21 -> -3750000 | AA22: =AA20+AA21 -> -3750000 | AB22: =SUM(X22:AA22) -> -15000000 | AC22: =AC20+AC21 -> -3750000 | AD22: =AD20+AD21 -> -3750000 | AE22: =AE20+AE21 -> -3750000 | AF22: =AF20+AF21 -> -3750000 | AG22: =SUM(AC22:AF22) -> -15000000 | AH22: =AH20+AH21 -> -3750000 | AI22: =AI20+AI21 -> -3750000 | AJ22: =AJ20+AJ21 -> -3750000 | AK22: =AK20+AK21 -> -3750000 | AL22: =SUM(AH22:AK22) -> -15000000
B23: Non-banking income | D23: =D19+D22 -> 1988906.2 | E23: =E19+E22 -> 7655625 | F23: =F19+F22 -> 13250156 | G23: =G19+G22 -> 18772500 | H23: =SUM(D23:G23) -> 41667188 | I23: =I19+I22 -> 24222656 | J23: =J19+J22 -> 29600625 | K23: =K19+K22 -> 34906406 | L23: =L19+L22 -> 40140000 | M23: =SUM(I23:L23) -> 1.2886969e+08 | N23: =N19+N22 -> 45301406 | O23: =O19+O22 -> 50390625 | P23: =P19+P22 -> 55407656 | Q23: =Q19+Q22 -> 60352500 | R23: =SUM(N23:Q23) -> 2.1145219e+08 | S23: =S19+S22 -> 65225156 | T23: =T19+T22 -> 70025625 | U23: =U19+U22 -> 74753906 | V23: =V19+V22 -> 79410000 | W23: =SUM(S23:V23) -> 2.8941469e+08 | X23: =X19+X22 -> 83993906 | Y23: =Y19+Y22 -> 88505625 | Z23: =Z19+Z22 -> 92945156 | AA23: =AA19+AA22 -> 97312500 | AB23: =SUM(X23:AA23) -> 3.6275719e+08 | AC23: =AC19+AC22 -> 96590625 | AD23: =AD19+AD22 -> 95868750 | AE23: =AE19+AE22 -> 95146875 | AF23: =AF19+AF22 -> 94425000 | AG23: =SUM(AC23:AF23) -> 382031250 | AH23: =AH19+AH22 -> 93703125 | AI23: =AI19+AI22 -> 92981250 | AJ23: =AJ19+AJ22 -> 92259375 | AK23: =AK19+AK22 -> 91537500 | AL23: =SUM(AH23:AK23) -> 370481250
